Workbook

Sheet TRIP MANAGER
A1: TRIP MANAGER — OVERFLIGHT & LANDING PERMIT ENGINE
A2: Enter DEP ICAO, ARR ICAO, ETD and REGISTRATION for each leg. Overflown countries and permit lines below recalculate automatically.
A4: 1 · TRIP & AIRCRAFT
A5: TRIP REFERENCE | B5: JTL-2608-001 | C5: Register status → | D5: =IF($B$5="","",IFERROR(INDEX(mayfly!$C:$C,MATCH($B$5,mayfly!$A:$A,0))&" | owner: "&INDEX(mayfly!$D:$D,MATCH($B$5,mayfly!$A:$A,0))&" | legs in register: "&COUNTIF(mayfly!$A:$A,$B$5),"NOT IN THE MAYFLY REGISTER - add it there first")) -> ACTIVE | owner: OPS DESK | legs in register: 4 | E5: BILL TO — DEFAULT (CLIENT ID) | F5: CLI-001
A6: OPERATOR | B6: JTL AVIATION, INC | C6: Operator on file for this tail → | E6: CLIENT / BILL-TO NAME | F6: =IF($F$5="","",IFERROR(INDEX(Clients!$D:$D,MATCH($F$5,Clients!$A:$A,0))&"","UNKNOWN CLIENT ID")) -> JTL AVIATION INC
A7: REGISTRATION | B7: N450GA | C7: =IF($B$7="","",IFERROR(IF(INDEX(Aircraft!$T:$T,MATCH($B$7,Aircraft!$B:$B,0))="","OPERATOR NAME NOT SET ON Operators SHEET",INDEX(Aircraft!$T:$T,MATCH($B$7,Aircraft!$B:$B,0))),"TAIL NOT IN FLEET — OPERATOR CANNOT BE VERIFIED")) -> OPERATOR NAME NOT SET ON Operators SHEET | E7: BILLING ADDRESS | F7: =IF($F$5="","",IFERROR(INDEX(Clients!$E:$E,MATCH($F$5,Clients!$A:$A,0))&IF(INDEX(Clients!$F:$F,MATCH($F$5,Clients!$A:$A,0))="","",", "&INDEX(Clients!$F:$F,MATCH($F$5,Clients!$A:$A,0)))&", "&INDEX(Clients!$G:$G,MATCH($F$5,Clients!$A:$A,0))&", "&INDEX(Clients!$H:$H,MATCH($F$5,Clients!$A:$A,0)),"UNKNOWN CLIENT ID")) -> 12065 PARK VIEW LANE, HOUSTON TX, USA
A8: AIRCRAFT TYPE (ICAO) | B8: =IF($B$7="","",IFERROR(INDEX(Aircraft!$C:$C,MATCH($B$7,Aircraft!$B:$B,0)),"NOT IN FLEET")) -> GLF6 | E8: BILLING EMAIL | F8: =IF($F$5="","",IFERROR(INDEX(Clients!$K:$K,MATCH($F$5,Clients!$A:$A,0))&"","UNKNOWN CLIENT ID")) -> ops@jetelio.com
A9: MTOW (KG) | B9: =IF($B$7="","",IFERROR(INDEX(Aircraft!$H:$H,MATCH($B$7,Aircraft!$B:$B,0)),"NOT IN FLEET")) -> 45178 | E9: CURRENCY | F9: =IF($F$5="","",IFERROR(INDEX(Clients!$M:$M,MATCH($F$5,Clients!$A:$A,0))&"","UNKNOWN CLIENT ID")) -> USD
A10: BLOCK SPEED (KTS) | B10: 470 | C10: =IF($B$8="","",IFERROR("Published cruise for "&$B$8&" is "&TEXT(INDEX('AIRCRAFT PERFORMANCE'!$E:$E,MATCH($B$8,'AIRCRAFT PERFORMANCE'!$A:$A,0)),"#,##0")&" kts - indicative only","Type not in the performance table")) -> Published cruise for GLF6 is 488 kts - indicative only | E10: PAYMENT TERMS | F10: =IF($F$5="","",IFERROR(INDEX(Clients!$N:$N,MATCH($F$5,Clients!$A:$A,0))&"","UNKNOWN CLIENT ID")) -> NET 30
A11: TAXI / CLIMB ALLOWANCE (HRS) | B11: 0.4 | C11: Added to each leg's airborne time | E11: ACCOUNT OWNED BY OPERATOR | F11: =IF($F$5="","",IFERROR(INDEX(Clients!$B:$B,MATCH($F$5,Clients!$A:$A,0))&"","UNKNOWN CLIENT ID")) -> OPV-20
A12: DEFAULT PERMIT LEAD TIME (HRS) | B12: 72 | C12: Used when a country has no lead time in the countries sheet | E12: ACCOUNT CHECK | F12: =IF($F$5="","",IFERROR(IF(INDEX(Clients!$B:$B,MATCH($F$5,Clients!$A:$A,0))=INDEX(Aircraft!$N:$N,MATCH($B$7,Aircraft!$B:$B,0)),"OK","BILL-TO BELONGS TO A DIFFERENT OPERATOR"),"CANNOT VERIFY - TAIL NOT IN FLEET")) -> BILL-TO BELONGS TO A DIFFERENT OPERATOR
A13: TRIP DISTANCE (NM) | B13: =SUM($J$18:$J$25) -> 9947
A14: TRIP EET (HRS) | B14: =ROUND(SUM($K$18:$K$25),2) -> 22.76
A16: 2 · LEGS (up to 8 · leg 2+ departure defaults to the previous leg's arrival, overwrite if needed)
A17: LEG | B17: DEP ICAO | C17: DEP AIRPORT | D17: DEP COUNTRY | E17: ETD DATE | F17: ETD (Z) | G17: ARR ICAO | H17: ARR AIRPORT | I17: ARR COUNTRY | J17: DIST (NM) | K17: EET (HRS) | L17: ETA DATE | M17: ETA (Z) | N17: BILL TO (LEG) | O17: DEP LAT | P17: DEP LON | Q17: ARR LAT | R17: ARR LON | S17: GC ANGLE (RAD) | T17: DEP ISO3 | U17: ARR ISO3 | V17: AVOID STATES / FIR (country name) | W17: INCLUDE STATES / FIR (country name) | X17: ROUTE CHECK | Y17: RANGE CHECK | AH17: NATIONALITY | AI17: FIRST? | AJ17: NAT RANK | AK17: GROUND ISO3 | AL17: GROUND AIRPORT | AM17: GROUND LEG | AN17: GROUND DATETIME | AO17: FIRST? | AP17: GH RANK
A18: L1 | B18: FALA | C18: =IF($B18="","",IFERROR(INDEX(airports!$E:$E,MATCH($B18,airports!$A:$A,0)),"ICAO NOT IN AIRPORTS")) -> Lanseria International Airport | D18: =IF($B18="","",IFERROR(INDEX(airports!$H:$H,MATCH($B18,airports!$A:$A,0)),"")) -> South Africa | E18: 46248 | F18: 0.375 | G18: FTTJ | H18: =IF($G18="","",IFERROR(INDEX(airports!$E:$E,MATCH($G18,airports!$A:$A,0)),"ICAO NOT IN AIRPORTS")) -> N'Djamena International Airport | I18: =IF($G18="","",IFERROR(INDEX(airports!$H:$H,MATCH($G18,airports!$A:$A,0)),"")) -> Chad | J18: =IF($S18="","",ROUND($S18*3440.065,0)) -> 2407 | K18: =IF(OR($J18="",$B$10=""),"",ROUND($J18/$B$10+$B$11,2)) -> 5.52 | L18: =IF(OR($E18="",$K18=""),"",INT($E18+$F18+$K18/24)) -> 46248 | M18: =IF($L18="","",MOD($E18+$F18+$K18/24,1)) -> 0.605 | N18: =IF($B18="","",$F$5) -> CLI-001 | O18: =IF($B18="","",IFERROR(INDEX(airports!$O:$O,MATCH($B18,airports!$A:$A,0)),"")) -> -25.93896 | P18: =IF($B18="","",IFERROR(INDEX(airports!$P:$P,MATCH($B18,airports!$A:$A,0)),"")) -> 27.92664 | Q18: =IF($G18="","",IFERROR(INDEX(airports!$O:$O,MATCH($G18,airports!$A:$A,0)),"")) -> 12.1337 | R18: =IF($G18="","",IFERROR(INDEX(airports!$P:$P,MATCH($G18,airports!$A:$A,0)),"")) -> 15.034 | S18: =IF(OR($O18="",$Q18=""),"",ACOS(MIN(1,SIN(RADIANS($O18))*SIN(RADIANS($Q18))+COS(RADIANS($O18))*COS(RADIANS($Q18))*COS(RADIANS($R18-$P18))))) -> 0.69965352 | T18: {=IF($O18="","",IFERROR(IF(INDEX(geo_grid!$B$2:$JU$231,INT(($O18+40)/0.5)+1,INT(($P18+30)/0.5)+1)="","",INDEX(geo_grid!$B$2:$JU$231,INT(($O18+40)/0.5)+1,INT(($P18+30)/0.5)+1)),"OUTSIDE GRID"))} -> ZAF | U18: {=IF($Q18="","",IFERROR(IF(INDEX(geo_grid!$B$2:$JU$231,INT(($Q18+40)/0.5)+1,INT(($R18+30)/0.5)+1)="","",INDEX(geo_grid!$B$2:$JU$231,INT(($Q18+40)/0.5)+1,INT(($R18+30)/0.5)+1)),"OUTSIDE GRID"))} -> TCD | X18: {=IF($B18="","",IF(AND($V18="",$W18=""),"NO CONSTRAINT",TRIM(IF($V18="","",IF(SUMPRODUCT(--((ISNUMBER(SEARCH(","&permit_calc!$A$3:$A$144&",",","&SUBSTITUTE(UPPER($V18)," ","")&","))+ISNUMBER(SEARCH(","&SUBSTITUTE(UPPER(permit_calc!$B$3:$B$144)," ","")&",",","&SUBSTITUTE(UPPER($V18)," ","")&",")))>0),--(INDEX(permit_calc!$C$3:$J$144,0,ROW()-17)>0))>0,"AVOID CONFLICT - track crosses an excluded state. ",""))&IF($W18="","",IF(SUMPRODUCT(--((ISNUMBER(SEARCH(","&permit_calc!$A$3:$A$144&",",","&SUBSTITUTE(UPPER($W18)," ","")&","))+ISNUMBER(SEARCH(","&SUBSTITUTE(UPPER(permit_calc!$B$3:$B$144)," ","")&",",","&SUBSTITUTE(UPPER($W18)," ","")&",")))>0),--(INDEX(permit_calc!$C$3:$J$144,0,ROW()-17)>0))<LEN($W18)-LEN(SUBSTITUTE($W18,",",""))+1,"INCLUDE NOT ON TRACK - required state not overflown. ","")))))} -> NO CONSTRAINT | Y18: =IF($B18="","",IFERROR(IF($J18>INDEX('AIRCRAFT PERFORMANCE'!$I:$I,MATCH($B$8,'AIRCRAFT PERFORMANCE'!$A:$A,0)),"EXCEEDS PRACTICAL RANGE OF "&TEXT(INDEX('AIRCRAFT PERFORMANCE'!$I:$I,MATCH($B$8,'AIRCRAFT PERFORMANCE'!$A:$A,0)),"#,##0")&" NM - TECHNICAL STOP REQUIRED","WITHIN RANGE"),"TYPE NOT IN PERFORMANCE TABLE")) -> WITHIN RANGE | AH18: =IFERROR(INDEX('PAX & CREW'!$L$3:$L$62,MATCH(ROW()-17,'PAX & CREW'!$AJ$3:$AJ$62,0)),"") -> United States | AI18: =IF($AH18="","",IF(COUNTIF($AH$18:$AH18,$AH18)=1,1,0)) -> 1 | AJ18: =IF($AI18=1,SUM($AI$18:$AI18),"") -> 1 | AK18: =IF($B$18="","",$T$18) -> ZAF | AL18: =IF($B$18="","",$B$18) -> FALA | AM18: =IF($B$18="","","L1") -> L1 | AN18: =IF($B$18="","",$E$18+$F$18) -> 46248.375 | AO18: =IF($AK18="","",IF(COUNTIF($AK$18:$AK18,$AK18)=1,1,0)) -> 1 | AP18: =IF($AO18=1,SUM($AO$18:$AO18),"") -> 1
A19: L2 | B19: FTTJ | C19: =IF($B19="","",IFERROR(INDEX(airports!$E:$E,MATCH($B19,airports!$A:$A,0)),"ICAO NOT IN AIRPORTS")) -> N'Djamena International Airport | D19: =IF($B19="","",IFERROR(INDEX(airports!$H:$H,MATCH($B19,airports!$A:$A,0)),"")) -> Chad | E19: 46250 | F19: 0.25 | G19: HECA | H19: =IF($G19="","",IFERROR(INDEX(airports!$E:$E,MATCH($G19,airports!$A:$A,0)),"ICAO NOT IN AIRPORTS")) -> Cairo International Airport | I19: =IF($G19="","",IFERROR(INDEX(airports!$H:$H,MATCH($G19,airports!$A:$A,0)),"")) -> Egypt | J19: =IF($S19="","",ROUND($S19*3440.065,0)) -> 1412 | K19: =IF(OR($J19="",$B$10=""),"",ROUND($J19/$B$10+$B$11,2)) -> 3.4 | L19: =IF(OR($E19="",$K19=""),"",INT($E19+$F19+$K19/24)) -> 46250 | M19: =IF($L19="","",MOD($E19+$F19+$K19/24,1)) -> 0.39166667 | N19: =IF($B19="","",$F$5) -> CLI-001 | O19: =IF($B19="","",IFERROR(INDEX(airports!$O:$O,MATCH($B19,airports!$A:$A,0)),"")) -> 12.1337 | P19: =IF($B19="","",IFERROR(INDEX(airports!$P:$P,MATCH($B19,airports!$A:$A,0)),"")) -> 15.034 | Q19: =IF($G19="","",IFERROR(INDEX(airports!$O:$O,MATCH($G19,airports!$A:$A,0)),"")) -> 30.11153 | R19: =IF($G19="","",IFERROR(INDEX(airports!$P:$P,MATCH($G19,airports!$A:$A,0)),"")) -> 31.39669 | S19: =IF(OR($O19="",$Q19=""),"",ACOS(MIN(1,SIN(RADIANS($O19))*SIN(RADIANS($Q19))+COS(RADIANS($O19))*COS(RADIANS($Q19))*COS(RADIANS($R19-$P19))))) -> 0.41049814 | T19: {=IF($O19="","",IFERROR(IF(INDEX(geo_grid!$B$2:$JU$231,INT(($O19+40)/0.5)+1,INT(($P19+30)/0.5)+1)="","",INDEX(geo_grid!$B$2:$JU$231,INT(($O19+40)/0.5)+1,INT(($P19+30)/0.5)+1)),"OUTSIDE GRID"))} -> TCD | U19: {=IF($Q19="","",IFERROR(IF(INDEX(geo_grid!$B$2:$JU$231,INT(($Q19+40)/0.5)+1,INT(($R19+30)/0.5)+1)="","",INDEX(geo_grid!$B$2:$JU$231,INT(($Q19+40)/0.5)+1,INT(($R19+30)/0.5)+1)),"OUTSIDE GRID"))} -> EGY | X19: {=IF($B19="","",IF(AND($V19="",$W19=""),"NO CONSTRAINT",TRIM(IF($V19="","",IF(SUMPRODUCT(--((ISNUMBER(SEARCH(","&permit_calc!$A$3:$A$144&",",","&SUBSTITUTE(UPPER($V19)," ","")&","))+ISNUMBER(SEARCH(","&SUBSTITUTE(UPPER(permit_calc!$B$3:$B$144)," ","")&",",","&SUBSTITUTE(UPPER($V19)," ","")&",")))>0),--(INDEX(permit_calc!$C$3:$J$144,0,ROW()-17)>0))>0,"AVOID CONFLICT - track crosses an excluded state. ",""))&IF($W19="","",IF(SUMPRODUCT(--((ISNUMBER(SEARCH(","&permit_calc!$A$3:$A$144&",",","&SUBSTITUTE(UPPER($W19)," ","")&","))+ISNUMBER(SEARCH(","&SUBSTITUTE(UPPER(permit_calc!$B$3:$B$144)," ","")&",",","&SUBSTITUTE(UPPER($W19)," ","")&",")))>0),--(INDEX(permit_calc!$C$3:$J$144,0,ROW()-17)>0))<LEN($W19)-LEN(SUBSTITUTE($W19,",",""))+1,"INCLUDE NOT ON TRACK - required state not overflown. ","")))))} -> NO CONSTRAINT | Y19: =IF($B19="","",IFERROR(IF($J19>INDEX('AIRCRAFT PERFORMANCE'!$I:$I,MATCH($B$8,'AIRCRAFT PERFORMANCE'!$A:$A,0)),"EXCEEDS PRACTICAL RANGE OF "&TEXT(INDEX('AIRCRAFT PERFORMANCE'!$I:$I,MATCH($B$8,'AIRCRAFT PERFORMANCE'!$A:$A,0)),"#,##0")&" NM - TECHNICAL STOP REQUIRED","WITHIN RANGE"),"TYPE NOT IN PERFORMANCE TABLE")) -> WITHIN RANGE | AH19: =IFERROR(INDEX('PAX & CREW'!$L$3:$L$62,MATCH(ROW()-17,'PAX & CREW'!$AJ$3:$AJ$62,0)),"") -> South Africa | AI19: =IF($AH19="","",IF(COUNTIF($AH$18:$AH19,$AH19)=1,1,0)) -> 1 | AJ19: =IF($AI19=1,SUM($AI$18:$AI19),"") -> 2 | AK19: =IF($U18="","",$U18) -> TCD | AL19: =IF($U18="","",$G18) -> FTTJ | AM19: =IF($U18="","",$A18) -> L1 | AN19: =IF($U18="","",$L18+$M18) -> 46248.605 | AO19: =IF($AK19="","",IF(COUNTIF($AK$18:$AK19,$AK19)=1,1,0)) -> 1 | AP19: =IF($AO19=1,SUM($AO$18:$AO19),"") -> 2
A20: L3 | B20: HECA | C20: =IF($B20="","",IFERROR(INDEX(airports!$E:$E,MATCH($B20,airports!$A:$A,0)),"ICAO NOT IN AIRPORTS")) -> Cairo International Airport | D20: =IF($B20="","",IFERROR(INDEX(airports!$H:$H,MATCH($B20,airports!$A:$A,0)),"")) -> Egypt | E20: 46251 | F20: 0.16666667 | G20: GMAD | H20: =IF($G20="","",IFERROR(INDEX(airports!$E:$E,MATCH($G20,airports!$A:$A,0)),"ICAO NOT IN AIRPORTS")) -> Al Massira Airport | I20: =IF($G20="","",IFERROR(INDEX(airports!$H:$H,MATCH($G20,airports!$A:$A,0)),"")) -> Morocco | J20: =IF($S20="","",ROUND($S20*3440.065,0)) -> 2106 | K20: =IF(OR($J20="",$B$10=""),"",ROUND($J20/$B$10+$B$11,2)) -> 4.88 | L20: =IF(OR($E20="",$K20=""),"",INT($E20+$F20+$K20/24)) -> 46251 | M20: =IF($L20="","",MOD($E20+$F20+$K20/24,1)) -> 0.37 | N20: =IF($B20="","",$F$5) -> CLI-001 | O20: =IF($B20="","",IFERROR(INDEX(airports!$O:$O,MATCH($B20,airports!$A:$A,0)),"")) -> 30.11153 | P20: =IF($B20="","",IFERROR(INDEX(airports!$P:$P,MATCH($B20,airports!$A:$A,0)),"")) -> 31.39669 | Q20: =IF($G20="","",IFERROR(INDEX(airports!$O:$O,MATCH($G20,airports!$A:$A,0)),"")) -> 30.32248 | R20: =IF($G20="","",IFERROR(INDEX(airports!$P:$P,MATCH($G20,airports!$A:$A,0)),"")) -> -9.412 | S20: =IF(OR($O20="",$Q20=""),"",ACOS(MIN(1,SIN(RADIANS($O20))*SIN(RADIANS($Q20))+COS(RADIANS($O20))*COS(RADIANS($Q20))*COS(RADIANS($R20-$P20))))) -> 0.61206182 | T20: {=IF($O20="","",IFERROR(IF(INDEX(geo_grid!$B$2:$JU$231,INT(($O20+40)/0.5)+1,INT(($P20+30)/0.5)+1)="","",INDEX(geo_grid!$B$2:$JU$231,INT(($O20+40)/0.5)+1,INT(($P20+30)/0.5)+1)),"OUTSIDE GRID"))} -> EGY | U20: {=IF($Q20="","",IFERROR(IF(INDEX(geo_grid!$B$2:$JU$231,INT(($Q20+40)/0.5)+1,INT(($R20+30)/0.5)+1)="","",INDEX(geo_grid!$B$2:$JU$231,INT(($Q20+40)/0.5)+1,INT(($R20+30)/0.5)+1)),"OUTSIDE GRID"))} -> MAR | X20: {=IF($B20="","",IF(AND($V20="",$W20=""),"NO CONSTRAINT",TRIM(IF($V20="","",IF(SUMPRODUCT(--((ISNUMBER(SEARCH(","&permit_calc!$A$3:$A$144&",",","&SUBSTITUTE(UPPER($V20)," ","")&","))+ISNUMBER(SEARCH(","&SUBSTITUTE(UPPER(permit_calc!$B$3:$B$144)," ","")&",",","&SUBSTITUTE(UPPER($V20)," ","")&",")))>0),--(INDEX(permit_calc!$C$3:$J$144,0,ROW()-17)>0))>0,"AVOID CONFLICT - track crosses an excluded state. ",""))&IF($W20="","",IF(SUMPRODUCT(--((ISNUMBER(SEARCH(","&permit_calc!$A$3:$A$144&",",","&SUBSTITUTE(UPPER($W20)," ","")&","))+ISNUMBER(SEARCH(","&SUBSTITUTE(UPPER(permit_calc!$B$3:$B$144)," ","")&",",","&SUBSTITUTE(UPPER($W20)," ","")&",")))>0),--(INDEX(permit_calc!$C$3:$J$144,0,ROW()-17)>0))<LEN($W20)-LEN(SUBSTITUTE($W20,",",""))+1,"INCLUDE NOT ON TRACK - required state not overflown. ","")))))} -> NO CONSTRAINT | Y20: =IF($B20="","",IFERROR(IF($J20>INDEX('AIRCRAFT PERFORMANCE'!$I:$I,MATCH($B$8,'AIRCRAFT PERFORMANCE'!$A:$A,0)),"EXCEEDS PRACTICAL RANGE OF "&TEXT(INDEX('AIRCRAFT PERFORMANCE'!$I:$I,MATCH($B$8,'AIRCRAFT PERFORMANCE'!$A:$A,0)),"#,##0")&" NM - TECHNICAL STOP REQUIRED","WITHIN RANGE"),"TYPE NOT IN PERFORMANCE TABLE")) -> WITHIN RANGE | AH20: =IFERROR(INDEX('PAX & CREW'!$L$3:$L$62,MATCH(ROW()-17,'PAX & CREW'!$AJ$3:$AJ$62,0)),"") -> Oman | AI20: =IF($AH20="","",IF(COUNTIF($AH$18:$AH20,$AH20)=1,1,0)) -> 1 | AJ20: =IF($AI20=1,SUM($AI$18:$AI20),"") -> 3 | AK20: =IF($U19="","",$U19) -> EGY | AL20: =IF($U19="","",$G19) -> HECA | AM20: =IF($U19="","",$A19) -> L2 | AN20: =IF($U19="","",$L19+$M19) -> 46250.392 | AO20: =IF($AK20="","",IF(COUNTIF($AK$18:$AK20,$AK20)=1,1,0)) -> 1 | AP20: =IF($AO20=1,SUM($AO$18:$AO20),"") -> 3
A21: L4 | B21: GMAD | C21: =IF($B21="","",IFERROR(INDEX(airports!$E:$E,MATCH($B21,airports!$A:$A,0)),"ICAO NOT IN AIRPORTS")) -> Al Massira Airport | D21: =IF($B21="","",IFERROR(INDEX(airports!$H:$H,MATCH($B21,airports!$A:$A,0)),"")) -> Morocco | E21: 46253 | F21: 0.041666667 | G21: FAOR | H21: =IF($G21="","",IFERROR(INDEX(airports!$E:$E,MATCH($G21,airports!$A:$A,0)),"ICAO NOT IN AIRPORTS")) -> O.R. Tambo International Airport | I21: =IF($G21="","",IFERROR(INDEX(airports!$H:$H,MATCH($G21,airports!$A:$A,0)),"")) -> South Africa | J21: =IF($S21="","",ROUND($S21*3440.065,0)) -> 4022 | K21: =IF(OR($J21="",$B$10=""),"",ROUND($J21/$B$10+$B$11,2)) -> 8.96 | L21: =IF(OR($E21="",$K21=""),"",INT($E21+$F21+$K21/24)) -> 46253 | M21: =IF($L21="","",MOD($E21+$F21+$K21/24,1)) -> 0.415 | N21: CLI-002 | O21: =IF($B21="","",IFERROR(INDEX(airports!$O:$O,MATCH($B21,airports!$A:$A,0)),"")) -> 30.32248 | P21: =IF($B21="","",IFERROR(INDEX(airports!$P:$P,MATCH($B21,airports!$A:$A,0)),"")) -> -9.412 | Q21: =IF($G21="","",IFERROR(INDEX(airports!$O:$O,MATCH($G21,airports!$A:$A,0)),"")) -> -26.14008 | R21: =IF($G21="","",IFERROR(INDEX(airports!$P:$P,MATCH($G21,airports!$A:$A,0)),"")) -> 28.2468 | S21: =IF(OR($O21="",$Q21=""),"",ACOS(MIN(1,SIN(RADIANS($O21))*SIN(RADIANS($Q21))+COS(RADIANS($O21))*COS(RADIANS($Q21))*COS(RADIANS($R21-$P21))))) -> 1.1690355 | T21: {=IF($O21="","",IFERROR(IF(INDEX(geo_grid!$B$2:$JU$231,INT(($O21+40)/0.5)+1,INT(($P21+30)/0.5)+1)="","",INDEX(geo_grid!$B$2:$JU$231,INT(($O21+40)/0.5)+1,INT(($P21+30)/0.5)+1)),"OUTSIDE GRID"))} -> MAR | U21: {=IF($Q21="","",IFERROR(IF(INDEX(geo_grid!$B$2:$JU$231,INT(($Q21+40)/0.5)+1,INT(($R21+30)/0.5)+1)="","",INDEX(geo_grid!$B$2:$JU$231,INT(($Q21+40)/0.5)+1,INT(($R21+30)/0.5)+1)),"OUTSIDE GRID"))} -> ZAF | X21: {=IF($B21="","",IF(AND($V21="",$W21=""),"NO CONSTRAINT",TRIM(IF($V21="","",IF(SUMPRODUCT(--((ISNUMBER(SEARCH(","&permit_calc!$A$3:$A$144&",",","&SUBSTITUTE(UPPER($V21)," ","")&","))+ISNUMBER(SEARCH(","&SUBSTITUTE(UPPER(permit_calc!$B$3:$B$144)," ","")&",",","&SUBSTITUTE(UPPER($V21)," ","")&",")))>0),--(INDEX(permit_calc!$C$3:$J$144,0,ROW()-17)>0))>0,"AVOID CONFLICT - track crosses an excluded state. ",""))&IF($W21="","",IF(SUMPRODUCT(--((ISNUMBER(SEARCH(","&permit_calc!$A$3:$A$144&",",","&SUBSTITUTE(UPPER($W21)," ","")&","))+ISNUMBER(SEARCH(","&SUBSTITUTE(UPPER(permit_calc!$B$3:$B$144)," ","")&",",","&SUBSTITUTE(UPPER($W21)," ","")&",")))>0),--(INDEX(permit_calc!$C$3:$J$144,0,ROW()-17)>0))<LEN($W21)-LEN(SUBSTITUTE($W21,",",""))+1,"INCLUDE NOT ON TRACK - required state not overflown. ","")))))} -> NO CONSTRAINT | Y21: =IF($B21="","",IFERROR(IF($J21>INDEX('AIRCRAFT PERFORMANCE'!$I:$I,MATCH($B$8,'AIRCRAFT PERFORMANCE'!$A:$A,0)),"EXCEEDS PRACTICAL RANGE OF "&TEXT(INDEX('AIRCRAFT PERFORMANCE'!$I:$I,MATCH($B$8,'AIRCRAFT PERFORMANCE'!$A:$A,0)),"#,##0")&" NM - TECHNICAL STOP REQUIRED","WITHIN RANGE"),"TYPE NOT IN PERFORMANCE TABLE")) -> WITHIN RANGE | AH21: =IFERROR(INDEX('PAX & CREW'!$L$3:$L$62,MATCH(ROW()-17,'PAX & CREW'!$AJ$3:$AJ$62,0)),"") -> South Africa | AI21: =IF($AH21="","",IF(COUNTIF($AH$18:$AH21,$AH21)=1,1,0)) -> 0 | AJ21: =IF($AI21=1,SUM($AI$18:$AI21),"") | AK21: =IF($U20="","",$U20) -> MAR | AL21: =IF($U20="","",$G20) -> GMAD | AM21: =IF($U20="","",$A20) -> L3 | AN21: =IF($U20="","",$L20+$M20) -> 46251.37 | AO21: =IF($AK21="","",IF(COUNTIF($AK$18:$AK21,$AK21)=1,1,0)) -> 1 | AP21: =IF($AO21=1,SUM($AO$18:$AO21),"") -> 4
A22: L5 | C22: =IF($B22="","",IFERROR(INDEX(airports!$E:$E,MATCH($B22,airports!$A:$A,0)),"ICAO NOT IN AIRPORTS")) | D22: =IF($B22="","",IFERROR(INDEX(airports!$H:$H,MATCH($B22,airports!$A:$A,0)),"")) | H22: =IF($G22="","",IFERROR(INDEX(airports!$E:$E,MATCH($G22,airports!$A:$A,0)),"ICAO NOT IN AIRPORTS")) | I22: =IF($G22="","",IFERROR(INDEX(airports!$H:$H,MATCH($G22,airports!$A:$A,0)),"")) | J22: =IF($S22="","",ROUND($S22*3440.065,0)) | K22: =IF(OR($J22="",$B$10=""),"",ROUND($J22/$B$10+$B$11,2)) | L22: =IF(OR($E22="",$K22=""),"",INT($E22+$F22+$K22/24)) | M22: =IF($L22="","",MOD($E22+$F22+$K22/24,1)) | N22: =IF($B22="","",$F$5) | O22: =IF($B22="","",IFERROR(INDEX(airports!$O:$O,MATCH($B22,airports!$A:$A,0)),"")) | P22: =IF($B22="","",IFERROR(INDEX(airports!$P:$P,MATCH($B22,airports!$A:$A,0)),"")) | Q22: =IF($G22="","",IFERROR(INDEX(airports!$O:$O,MATCH($G22,airports!$A:$A,0)),"")) | R22: =IF($G22="","",IFERROR(INDEX(airports!$P:$P,MATCH($G22,airports!$A:$A,0)),"")) | S22: =IF(OR($O22="",$Q22=""),"",ACOS(MIN(1,SIN(RADIANS($O22))*SIN(RADIANS($Q22))+COS(RADIANS($O22))*COS(RADIANS($Q22))*COS(RADIANS($R22-$P22))))) | T22: {=IF($O22="","",IFERROR(IF(INDEX(geo_grid!$B$2:$JU$231,INT(($O22+40)/0.5)+1,INT(($P22+30)/0.5)+1)="","",INDEX(geo_grid!$B$2:$JU$231,INT(($O22+40)/0.5)+1,INT(($P22+30)/0.5)+1)),"OUTSIDE GRID"))} | U22: {=IF($Q22="","",IFERROR(IF(INDEX(geo_grid!$B$2:$JU$231,INT(($Q22+40)/0.5)+1,INT(($R22+30)/0.5)+1)="","",INDEX(geo_grid!$B$2:$JU$231,INT(($Q22+40)/0.5)+1,INT(($R22+30)/0.5)+1)),"OUTSIDE GRID"))} | X22: {=IF($B22="","",IF(AND($V22="",$W22=""),"NO CONSTRAINT",TRIM(IF($V22="","",IF(SUMPRODUCT(--((ISNUMBER(SEARCH(","&permit_calc!$A$3:$A$144&",",","&SUBSTITUTE(UPPER($V22)," ","")&","))+ISNUMBER(SEARCH(","&SUBSTITUTE(UPPER(permit_calc!$B$3:$B$144)," ","")&",",","&SUBSTITUTE(UPPER($V22)," ","")&",")))>0),--(INDEX(permit_calc!$C$3:$J$144,0,ROW()-17)>0))>0,"AVOID CONFLICT - track crosses an excluded state. ",""))&IF($W22="","",IF(SUMPRODUCT(--((ISNUMBER(SEARCH(","&permit_calc!$A$3:$A$144&",",","&SUBSTITUTE(UPPER($W22)," ","")&","))+ISNUMBER(SEARCH(","&SUBSTITUTE(UPPER(permit_calc!$B$3:$B$144)," ","")&",",","&SUBSTITUTE(UPPER($W22)," ","")&",")))>0),--(INDEX(permit_calc!$C$3:$J$144,0,ROW()-17)>0))<LEN($W22)-LEN(SUBSTITUTE($W22,",",""))+1,"INCLUDE NOT ON TRACK - required state not overflown. ","")))))} | Y22: =IF($B22="","",IFERROR(IF($J22>INDEX('AIRCRAFT PERFORMANCE'!$I:$I,MATCH($B$8,'AIRCRAFT PERFORMANCE'!$A:$A,0)),"EXCEEDS PRACTICAL RANGE OF "&TEXT(INDEX('AIRCRAFT PERFORMANCE'!$I:$I,MATCH($B$8,'AIRCRAFT PERFORMANCE'!$A:$A,0)),"#,##0")&" NM - TECHNICAL STOP REQUIRED","WITHIN RANGE"),"TYPE NOT IN PERFORMANCE TABLE")) | AH22: =IFERROR(INDEX('PAX & CREW'!$L$3:$L$62,MATCH(ROW()-17,'PAX & CREW'!$AJ$3:$AJ$62,0)),"") | AI22: =IF($AH22="","",IF(COUNTIF($AH$18:$AH22,$AH22)=1,1,0)) | AJ22: =IF($AI22=1,SUM($AI$18:$AI22),"") | AK22: =IF($U21="","",$U21) -> ZAF | AL22: =IF($U21="","",$G21) -> FAOR | AM22: =IF($U21="","",$A21) -> L4 | AN22: =IF($U21="","",$L21+$M21) -> 46253.415 | AO22: =IF($AK22="","",IF(COUNTIF($AK$18:$AK22,$AK22)=1,1,0)) -> 0 | AP22: =IF($AO22=1,SUM($AO$18:$AO22),"")
A23: L6 | B23: =IF($G22="","",$G22) | C23: =IF($B23="","",IFERROR(INDEX(airports!$E:$E,MATCH($B23,airports!$A:$A,0)),"ICAO NOT IN AIRPORTS")) | D23: =IF($B23="","",IFERROR(INDEX(airports!$H:$H,MATCH($B23,airports!$A:$A,0)),"")) | H23: =IF($G23="","",IFERROR(INDEX(airports!$E:$E,MATCH($G23,airports!$A:$A,0)),"ICAO NOT IN AIRPORTS")) | I23: =IF($G23="","",IFERROR(INDEX(airports!$H:$H,MATCH($G23,airports!$A:$A,0)),"")) | J23: =IF($S23="","",ROUND($S23*3440.065,0)) | K23: =IF(OR($J23="",$B$10=""),"",ROUND($J23/$B$10+$B$11,2)) | L23: =IF(OR($E23="",$K23=""),"",INT($E23+$F23+$K23/24)) | M23: =IF($L23="","",MOD($E23+$F23+$K23/24,1)) | N23: =IF($B23="","",$F$5) | O23: =IF($B23="","",IFERROR(INDEX(airports!$O:$O,MATCH($B23,airports!$A:$A,0)),"")) | P23: =IF($B23="","",IFERROR(INDEX(airports!$P:$P,MATCH($B23,airports!$A:$A,0)),"")) | Q23: =IF($G23="","",IFERROR(INDEX(airports!$O:$O,MATCH($G23,airports!$A:$A,0)),"")) | R23: =IF($G23="","",IFERROR(INDEX(airports!$P:$P,MATCH($G23,airports!$A:$A,0)),"")) | S23: =IF(OR($O23="",$Q23=""),"",ACOS(MIN(1,SIN(RADIANS($O23))*SIN(RADIANS($Q23))+COS(RADIANS($O23))*COS(RADIANS($Q23))*COS(RADIANS($R23-$P23))))) | T23: {=IF($O23="","",IFERROR(IF(INDEX(geo_grid!$B$2:$JU$231,INT(($O23+40)/0.5)+1,INT(($P23+30)/0.5)+1)="","",INDEX(geo_grid!$B$2:$JU$231,INT(($O23+40)/0.5)+1,INT(($P23+30)/0.5)+1)),"OUTSIDE GRID"))} | U23: {=IF($Q23="","",IFERROR(IF(INDEX(geo_grid!$B$2:$JU$231,INT(($Q23+40)/0.5)+1,INT(($R23+30)/0.5)+1)="","",INDEX(geo_grid!$B$2:$JU$231,INT(($Q23+40)/0.5)+1,INT(($R23+30)/0.5)+1)),"OUTSIDE GRID"))} | X23: {=IF($B23="","",IF(AND($V23="",$W23=""),"NO CONSTRAINT",TRIM(IF($V23="","",IF(SUMPRODUCT(--((ISNUMBER(SEARCH(","&permit_calc!$A$3:$A$144&",",","&SUBSTITUTE(UPPER($V23)," ","")&","))+ISNUMBER(SEARCH(","&SUBSTITUTE(UPPER(permit_calc!$B$3:$B$144)," ","")&",",","&SUBSTITUTE(UPPER($V23)," ","")&",")))>0),--(INDEX(permit_calc!$C$3:$J$144,0,ROW()-17)>0))>0,"AVOID CONFLICT - track crosses an excluded state. ",""))&IF($W23="","",IF(SUMPRODUCT(--((ISNUMBER(SEARCH(","&permit_calc!$A$3:$A$144&",",","&SUBSTITUTE(UPPER($W23)," ","")&","))+ISNUMBER(SEARCH(","&SUBSTITUTE(UPPER(permit_calc!$B$3:$B$144)," ","")&",",","&SUBSTITUTE(UPPER($W23)," ","")&",")))>0),--(INDEX(permit_calc!$C$3:$J$144,0,ROW()-17)>0))<LEN($W23)-LEN(SUBSTITUTE($W23,",",""))+1,"INCLUDE NOT ON TRACK - required state not overflown. ","")))))} | Y23: =IF($B23="","",IFERROR(IF($J23>INDEX('AIRCRAFT PERFORMANCE'!$I:$I,MATCH($B$8,'AIRCRAFT PERFORMANCE'!$A:$A,0)),"EXCEEDS PRACTICAL RANGE OF "&TEXT(INDEX('AIRCRAFT PERFORMANCE'!$I:$I,MATCH($B$8,'AIRCRAFT PERFORMANCE'!$A:$A,0)),"#,##0")&" NM - TECHNICAL STOP REQUIRED","WITHIN RANGE"),"TYPE NOT IN PERFORMANCE TABLE")) | AH23: =IFERROR(INDEX('PAX & CREW'!$L$3:$L$62,MATCH(ROW()-17,'PAX & CREW'!$AJ$3:$AJ$62,0)),"") | AI23: =IF($AH23="","",IF(COUNTIF($AH$18:$AH23,$AH23)=1,1,0)) | AJ23: =IF($AI23=1,SUM($AI$18:$AI23),"") | AK23: =IF($U22="","",$U22) | AL23: =IF($U22="","",$G22) | AM23: =IF($U22="","",$A22) | AN23: =IF($U22="","",$L22+$M22) | AO23: =IF($AK23="","",IF(COUNTIF($AK$18:$AK23,$AK23)=1,1,0)) | AP23: =IF($AO23=1,SUM($AO$18:$AO23),"")
A24: L7 | B24: =IF($G23="","",$G23) | C24: =IF($B24="","",IFERROR(INDEX(airports!$E:$E,MATCH($B24,airports!$A:$A,0)),"ICAO NOT IN AIRPORTS")) | D24: =IF($B24="","",IFERROR(INDEX(airports!$H:$H,MATCH($B24,airports!$A:$A,0)),"")) | H24: =IF($G24="","",IFERROR(INDEX(airports!$E:$E,MATCH($G24,airports!$A:$A,0)),"ICAO NOT IN AIRPORTS")) | I24: =IF($G24="","",IFERROR(INDEX(airports!$H:$H,MATCH($G24,airports!$A:$A,0)),"")) | J24: =IF($S24="","",ROUND($S24*3440.065,0)) | K24: =IF(OR($J24="",$B$10=""),"",ROUND($J24/$B$10+$B$11,2)) | L24: =IF(OR($E24="",$K24=""),"",INT($E24+$F24+$K24/24)) | M24: =IF($L24="","",MOD($E24+$F24+$K24/24,1)) | N24: =IF($B24="","",$F$5) | O24: =IF($B24="","",IFERROR(INDEX(airports!$O:$O,MATCH($B24,airports!$A:$A,0)),"")) | P24: =IF($B24="","",IFERROR(INDEX(airports!$P:$P,MATCH($B24,airports!$A:$A,0)),"")) | Q24: =IF($G24="","",IFERROR(INDEX(airports!$O:$O,MATCH($G24,airports!$A:$A,0)),"")) | R24: =IF($G24="","",IFERROR(INDEX(airports!$P:$P,MATCH($G24,airports!$A:$A,0)),"")) | S24: =IF(OR($O24="",$Q24=""),"",ACOS(MIN(1,SIN(RADIANS($O24))*SIN(RADIANS($Q24))+COS(RADIANS($O24))*COS(RADIANS($Q24))*COS(RADIANS($R24-$P24))))) | T24: {=IF($O24="","",IFERROR(IF(INDEX(geo_grid!$B$2:$JU$231,INT(($O24+40)/0.5)+1,INT(($P24+30)/0.5)+1)="","",INDEX(geo_grid!$B$2:$JU$231,INT(($O24+40)/0.5)+1,INT(($P24+30)/0.5)+1)),"OUTSIDE GRID"))} | U24: {=IF($Q24="","",IFERROR(IF(INDEX(geo_grid!$B$2:$JU$231,INT(($Q24+40)/0.5)+1,INT(($R24+30)/0.5)+1)="","",INDEX(geo_grid!$B$2:$JU$231,INT(($Q24+40)/0.5)+1,INT(($R24+30)/0.5)+1)),"OUTSIDE GRID"))} | X24: {=IF($B24="","",IF(AND($V24="",$W24=""),"NO CONSTRAINT",TRIM(IF($V24="","",IF(SUMPRODUCT(--((ISNUMBER(SEARCH(","&permit_calc!$A$3:$A$144&",",","&SUBSTITUTE(UPPER($V24)," ","")&","))+ISNUMBER(SEARCH(","&SUBSTITUTE(UPPER(permit_calc!$B$3:$B$144)," ","")&",",","&SUBSTITUTE(UPPER($V24)," ","")&",")))>0),--(INDEX(permit_calc!$C$3:$J$144,0,ROW()-17)>0))>0,"AVOID CONFLICT - track crosses an excluded state. ",""))&IF($W24="","",IF(SUMPRODUCT(--((ISNUMBER(SEARCH(","&permit_calc!$A$3:$A$144&",",","&SUBSTITUTE(UPPER($W24)," ","")&","))+ISNUMBER(SEARCH(","&SUBSTITUTE(UPPER(permit_calc!$B$3:$B$144)," ","")&",",","&SUBSTITUTE(UPPER($W24)," ","")&",")))>0),--(INDEX(permit_calc!$C$3:$J$144,0,ROW()-17)>0))<LEN($W24)-LEN(SUBSTITUTE($W24,",",""))+1,"INCLUDE NOT ON TRACK - required state not overflown. ","")))))} | Y24: =IF($B24="","",IFERROR(IF($J24>INDEX('AIRCRAFT PERFORMANCE'!$I:$I,MATCH($B$8,'AIRCRAFT PERFORMANCE'!$A:$A,0)),"EXCEEDS PRACTICAL RANGE OF "&TEXT(INDEX('AIRCRAFT PERFORMANCE'!$I:$I,MATCH($B$8,'AIRCRAFT PERFORMANCE'!$A:$A,0)),"#,##0")&" NM - TECHNICAL STOP REQUIRED","WITHIN RANGE"),"TYPE NOT IN PERFORMANCE TABLE")) | AH24: =IFERROR(INDEX('PAX & CREW'!$L$3:$L$62,MATCH(ROW()-17,'PAX & CREW'!$AJ$3:$AJ$62,0)),"") | AI24: =IF($AH24="","",IF(COUNTIF($AH$18:$AH24,$AH24)=1,1,0)) | AJ24: =IF($AI24=1,SUM($AI$18:$AI24),"") | AK24: =IF($U23="","",$U23) | AL24: =IF($U23="","",$G23) | AM24: =IF($U23="","",$A23) | AN24: =IF($U23="","",$L23+$M23) | AO24: =IF($AK24="","",IF(COUNTIF($AK$18:$AK24,$AK24)=1,1,0)) | AP24: =IF($AO24=1,SUM($AO$18:$AO24),"")
A25: L8 | B25: =IF($G24="","",$G24) | C25: =IF($B25="","",IFERROR(INDEX(airports!$E:$E,MATCH($B25,airports!$A:$A,0)),"ICAO NOT IN AIRPORTS")) | D25: =IF($B25="","",IFERROR(INDEX(airports!$H:$H,MATCH($B25,airports!$A:$A,0)),"")) | H25: =IF($G25="","",IFERROR(INDEX(airports!$E:$E,MATCH($G25,airports!$A:$A,0)),"ICAO NOT IN AIRPORTS")) | I25: =IF($G25="","",IFERROR(INDEX(airports!$H:$H,MATCH($G25,airports!$A:$A,0)),"")) | J25: =IF($S25="","",ROUND($S25*3440.065,0)) | K25: =IF(OR($J25="",$B$10=""),"",ROUND($J25/$B$10+$B$11,2)) | L25: =IF(OR($E25="",$K25=""),"",INT($E25+$F25+$K25/24)) | M25: =IF($L25="","",MOD($E25+$F25+$K25/24,1)) | N25: =IF($B25="","",$F$5) | O25: =IF($B25="","",IFERROR(INDEX(airports!$O:$O,MATCH($B25,airports!$A:$A,0)),"")) | P25: =IF($B25="","",IFERROR(INDEX(airports!$P:$P,MATCH($B25,airports!$A:$A,0)),"")) | Q25: =IF($G25="","",IFERROR(INDEX(airports!$O:$O,MATCH($G25,airports!$A:$A,0)),"")) | R25: =IF($G25="","",IFERROR(INDEX(airports!$P:$P,MATCH($G25,airports!$A:$A,0)),"")) | S25: =IF(OR($O25="",$Q25=""),"",ACOS(MIN(1,SIN(RADIANS($O25))*SIN(RADIANS($Q25))+COS(RADIANS($O25))*COS(RADIANS($Q25))*COS(RADIANS($R25-$P25))))) | T25: {=IF($O25="","",IFERROR(IF(INDEX(geo_grid!$B$2:$JU$231,INT(($O25+40)/0.5)+1,INT(($P25+30)/0.5)+1)="","",INDEX(geo_grid!$B$2:$JU$231,INT(($O25+40)/0.5)+1,INT(($P25+30)/0.5)+1)),"OUTSIDE GRID"))} | U25: {=IF($Q25="","",IFERROR(IF(INDEX(geo_grid!$B$2:$JU$231,INT(($Q25+40)/0.5)+1,INT(($R25+30)/0.5)+1)="","",INDEX(geo_grid!$B$2:$JU$231,INT(($Q25+40)/0.5)+1,INT(($R25+30)/0.5)+1)),"OUTSIDE GRID"))} | X25: {=IF($B25="","",IF(AND($V25="",$W25=""),"NO CONSTRAINT",TRIM(IF($V25="","",IF(SUMPRODUCT(--((ISNUMBER(SEARCH(","&permit_calc!$A$3:$A$144&",",","&SUBSTITUTE(UPPER($V25)," ","")&","))+ISNUMBER(SEARCH(","&SUBSTITUTE(UPPER(permit_calc!$B$3:$B$144)," ","")&",",","&SUBSTITUTE(UPPER($V25)," ","")&",")))>0),--(INDEX(permit_calc!$C$3:$J$144,0,ROW()-17)>0))>0,"AVOID CONFLICT - track crosses an excluded state. ",""))&IF($W25="","",IF(SUMPRODUCT(--((ISNUMBER(SEARCH(","&permit_calc!$A$3:$A$144&",",","&SUBSTITUTE(UPPER($W25)," ","")&","))+ISNUMBER(SEARCH(","&SUBSTITUTE(UPPER(permit_calc!$B$3:$B$144)," ","")&",",","&SUBSTITUTE(UPPER($W25)," ","")&",")))>0),--(INDEX(permit_calc!$C$3:$J$144,0,ROW()-17)>0))<LEN($W25)-LEN(SUBSTITUTE($W25,",",""))+1,"INCLUDE NOT ON TRACK - required state not overflown. ","")))))} | Y25: =IF($B25="","",IFERROR(IF($J25>INDEX('AIRCRAFT PERFORMANCE'!$I:$I,MATCH($B$8,'AIRCRAFT PERFORMANCE'!$A:$A,0)),"EXCEEDS PRACTICAL RANGE OF "&TEXT(INDEX('AIRCRAFT PERFORMANCE'!$I:$I,MATCH($B$8,'AIRCRAFT PERFORMANCE'!$A:$A,0)),"#,##0")&" NM - TECHNICAL STOP REQUIRED","WITHIN RANGE"),"TYPE NOT IN PERFORMANCE TABLE")) | AH25: =IFERROR(INDEX('PAX & CREW'!$L$3:$L$62,MATCH(ROW()-17,'PAX & CREW'!$AJ$3:$AJ$62,0)),"") | AI25: =IF($AH25="","",IF(COUNTIF($AH$18:$AH25,$AH25)=1,1,0)) | AJ25: =IF($AI25=1,SUM($AI$18:$AI25),"") | AK25: =IF($U24="","",$U24) | AL25: =IF($U24="","",$G24) | AM25: =IF($U24="","",$A24) | AN25: =IF($U24="","",$L24+$M24) | AO25: =IF($AK25="","",IF(COUNTIF($AK$18:$AK25,$AK25)=1,1,0)) | AP25: =IF($AO25=1,SUM($AO$18:$AO25),"")
A26: TOTALS | J26: =SUM($J$18:$J$25) -> 9947 | K26: =ROUND(SUM($K$18:$K$25),2) -> 22.76 | L26: =IF(OR($E26="",$K26=""),"",INT($E26+$F26+$K26/24)) | M26: =IF($L26="","",MOD($E26+$F26+$K26/24,1)) | AH26: =IFERROR(INDEX('PAX & CREW'!$L$3:$L$62,MATCH(ROW()-17,'PAX & CREW'!$AJ$3:$AJ$62,0)),"") | AI26: =IF($AH26="","",IF(COUNTIF($AH$18:$AH26,$AH26)=1,1,0)) | AJ26: =IF($AI26=1,SUM($AI$18:$AI26),"") | AK26: =IF($U25="","",$U25) | AL26: =IF($U25="","",$G25) | AM26: =IF($U25="","",$A25) | AN26: =IF($U25="","",$L25+$M25) | AO26: =IF($AK26="","",IF(COUNTIF($AK$18:$AK26,$AK26)=1,1,0)) | AP26: =IF($AO26=1,SUM($AO$18:$AO26),"")
V27: Enter ISO3 codes separated by commas, e.g. LBY, SDN. FIR boundaries are approximated by state airspace — verify against the AIP. AVOID flags a conflict when the great-circle track crosses an excluded state; INCLUDE flags when a required state is not on track. Re-route by inserting a technical stop or adjusting the leg. | AH27: =IFERROR(INDEX('PAX & CREW'!$L$3:$L$62,MATCH(ROW()-17,'PAX & CREW'!$AJ$3:$AJ$62,0)),"") | AI27: =IF($AH27="","",IF(COUNTIF($AH$18:$AH27,$AH27)=1,1,0)) | AJ27: =IF($AI27=1,SUM($AI$18:$AI27),"")
A28: 3 · PERMITS (overflight for every en-route country except the leg's departure state and its destination; the destination raises a landing permit — ground services are in section 4) | AH28: =IFERROR(INDEX('PAX & CREW'!$L$3:$L$62,MATCH(ROW()-17,'PAX & CREW'!$AJ$3:$AJ$62,0)),"") | AI28: =IF($AH28="","",IF(COUNTIF($AH$18:$AH28,$AH28)=1,1,0)) | AJ28: =IF($AI28=1,SUM($AI$18:$AI28),"")
A29: # | B29: COUNTRY | C29: ISO3 | D29: PERMIT TYPE | E29: AIRPORT | F29: LEGS | G29: PROVIDER | H29: REF DATE (UTC) | I29: LEAD TIME (HRS) | J29: FILE BY (UTC) | K29: DAYS TO DEADLINE | L29: REQUIRED | M29: STATUS | AE29: ROW KIND | AF29: LEG INDEX | AH29: =IFERROR(INDEX('PAX & CREW'!$L$3:$L$62,MATCH(ROW()-17,'PAX & CREW'!$AJ$3:$AJ$62,0)),"") | AI29: =IF($AH29="","",IF(COUNTIF($AH$18:$AH29,$AH29)=1,1,0)) | AJ29: =IF($AI29=1,SUM($AI$18:$AI29),"")
A30: =IF(ROW()-29>COUNTIF(permit_calc!$L$3:$L$144,1)+COUNTA($G$18:$G$25),"",ROW()-29) -> 1 | B30: =IF($A30="","",IF($AE30="OVF",INDEX(permit_calc!$B$3:$B$144,MATCH($A30,permit_calc!$N$3:$N$144,0)),IFERROR(INDEX(countries!$B:$B,MATCH($C30,countries!$D:$D,0)),$C30))) -> Botswana | C30: {=IF($A30="","",IF($AE30="OVF",INDEX(permit_calc!$A$3:$A$144,MATCH($A30,permit_calc!$N$3:$N$144,0)),INDEX($U$18:$U$25,$AF30)))} -> BWA | D30: =IF($A30="","",$AE30) -> OVF | E30: {=IF($A30="","",IF($AE30="OVF","",INDEX($G$18:$G$25,$AF30)))} | F30: {=IF($A30="","",IF($AE30="OVF",INDEX(permit_calc!$M$3:$M$144,MATCH($A30,permit_calc!$N$3:$N$144,0)),INDEX($A$18:$A$25,$AF30)))} -> L1, L4 | G30: JTL | H30: {=IF($A30="","",IF($AE30="OVF",INDEX($E$18:$E$25,INDEX(permit_calc!$O$3:$O$144,MATCH($A30,permit_calc!$N$3:$N$144,0)))+INDEX($F$18:$F$25,INDEX(permit_calc!$O$3:$O$144,MATCH($A30,permit_calc!$N$3:$N$144,0))),INDEX($L$18:$L$25,$AF30)+INDEX($M$18:$M$25,$AF30)))} -> 46248.375 | I30: =IF($A30="","",IFERROR(IF(INDEX(countries!$I:$I,MATCH($C30,countries!$D:$D,0))=0,$B$12,INDEX(countries!$I:$I,MATCH($C30,countries!$D:$D,0))),$B$12)) -> 72 | J30: =IF($A30="","",$H30-$I30/24) -> 46245.375 | K30: =IF($A30="","",ROUND($J30-NOW(),1)) -> 1.8 | L30: =IF($A30="","",IF($AE30="OVF",IFERROR(INDEX(countries!$G:$G,MATCH($C30,countries!$D:$D,0)),"VERIFY"),IFERROR(INDEX(countries!$H:$H,MATCH($C30,countries!$D:$D,0)),"VERIFY"))) -> REQUIRED | M30: =IF($A30="","",IF(OR(UPPER($G30)="OWN",UPPER($G30)="EXCLUDED"),"CLIENT ARRANGING",IF($K30<0,"OVERDUE",IF($K30<1,"URGENT - FILE NOW",IF($K30<3,"DUE SOON","PENDING"))))) -> DUE SOON | AE30: =IF($A30="","",IF($A30<=COUNTIF(permit_calc!$L$3:$L$144,1),"OVF","LDG")) -> OVF | AF30: =IF($AE30="","",IF($AE30="OVF","",$A30-COUNTIF(permit_calc!$L$3:$L$144,1))) | AH30: =IFERROR(INDEX('PAX & CREW'!$L$3:$L$62,MATCH(ROW()-17,'PAX & CREW'!$AJ$3:$AJ$62,0)),"") | AI30: =IF($AH30="","",IF(COUNTIF($AH$18:$AH30,$AH30)=1,1,0)) | AJ30: =IF($AI30=1,SUM($AI$18:$AI30),"")
A31: =IF(ROW()-29>COUNTIF(permit_calc!$L$3:$L$144,1)+COUNTA($G$18:$G$25),"",ROW()-29) -> 2 | B31: =IF($A31="","",IF($AE31="OVF",INDEX(permit_calc!$B$3:$B$144,MATCH($A31,permit_calc!$N$3:$N$144,0)),IFERROR(INDEX(countries!$B:$B,MATCH($C31,countries!$D:$D,0)),$C31))) -> Namibia | C31: {=IF($A31="","",IF($AE31="OVF",INDEX(permit_calc!$A$3:$A$144,MATCH($A31,permit_calc!$N$3:$N$144,0)),INDEX($U$18:$U$25,$AF31)))} -> NAM | D31: =IF($A31="","",$AE31) -> OVF | E31: {=IF($A31="","",IF($AE31="OVF","",INDEX($G$18:$G$25,$AF31)))} | F31: {=IF($A31="","",IF($AE31="OVF",INDEX(permit_calc!$M$3:$M$144,MATCH($A31,permit_calc!$N$3:$N$144,0)),INDEX($A$18:$A$25,$AF31)))} -> L1, L4 | G31: JTL | H31: {=IF($A31="","",IF($AE31="OVF",INDEX($E$18:$E$25,INDEX(permit_calc!$O$3:$O$144,MATCH($A31,permit_calc!$N$3:$N$144,0)))+INDEX($F$18:$F$25,INDEX(permit_calc!$O$3:$O$144,MATCH($A31,permit_calc!$N$3:$N$144,0))),INDEX($L$18:$L$25,$AF31)+INDEX($M$18:$M$25,$AF31)))} -> 46248.375 | I31: =IF($A31="","",IFERROR(IF(INDEX(countries!$I:$I,MATCH($C31,countries!$D:$D,0))=0,$B$12,INDEX(countries!$I:$I,MATCH($C31,countries!$D:$D,0))),$B$12)) -> 72 | J31: =IF($A31="","",$H31-$I31/24) -> 46245.375 | K31: =IF($A31="","",ROUND($J31-NOW(),1)) -> 1.8 | L31: =IF($A31="","",IF($AE31="OVF",IFERROR(INDEX(countries!$G:$G,MATCH($C31,countries!$D:$D,0)),"VERIFY"),IFERROR(INDEX(countries!$H:$H,MATCH($C31,countries!$D:$D,0)),"VERIFY"))) -> REQUIRED | M31: =IF($A31="","",IF(OR(UPPER($G31)="OWN",UPPER($G31)="EXCLUDED"),"CLIENT ARRANGING",IF($K31<0,"OVERDUE",IF($K31<1,"URGENT - FILE NOW",IF($K31<3,"DUE SOON","PENDING"))))) -> DUE SOON | AE31: =IF($A31="","",IF($A31<=COUNTIF(permit_calc!$L$3:$L$144,1),"OVF","LDG")) -> OVF | AF31: =IF($AE31="","",IF($AE31="OVF","",$A31-COUNTIF(permit_calc!$L$3:$L$144,1))) | AH31: =IFERROR(INDEX('PAX & CREW'!$L$3:$L$62,MATCH(ROW()-17,'PAX & CREW'!$AJ$3:$AJ$62,0)),"") | AI31: =IF($AH31="","",IF(COUNTIF($AH$18:$AH31,$AH31)=1,1,0)) | AJ31: =IF($AI31=1,SUM($AI$18:$AI31),"")
A32: =IF(ROW()-29>COUNTIF(permit_calc!$L$3:$L$144,1)+COUNTA($G$18:$G$25),"",ROW()-29) -> 3 | B32: =IF($A32="","",IF($AE32="OVF",INDEX(permit_calc!$B$3:$B$144,MATCH($A32,permit_calc!$N$3:$N$144,0)),IFERROR(INDEX(countries!$B:$B,MATCH($C32,countries!$D:$D,0)),$C32))) -> Zambia | C32: {=IF($A32="","",IF($AE32="OVF",INDEX(permit_calc!$A$3:$A$144,MATCH($A32,permit_calc!$N$3:$N$144,0)),INDEX($U$18:$U$25,$AF32)))} -> ZMB | D32: =IF($A32="","",$AE32) -> OVF | E32: {=IF($A32="","",IF($AE32="OVF","",INDEX($G$18:$G$25,$AF32)))} | F32: {=IF($A32="","",IF($AE32="OVF",INDEX(permit_calc!$M$3:$M$144,MATCH($A32,permit_calc!$N$3:$N$144,0)),INDEX($A$18:$A$25,$AF32)))} -> L1 | G32: JTL | H32: {=IF($A32="","",IF($AE32="OVF",INDEX($E$18:$E$25,INDEX(permit_calc!$O$3:$O$144,MATCH($A32,permit_calc!$N$3:$N$144,0)))+INDEX($F$18:$F$25,INDEX(permit_calc!$O$3:$O$144,MATCH($A32,permit_calc!$N$3:$N$144,0))),INDEX($L$18:$L$25,$AF32)+INDEX($M$18:$M$25,$AF32)))} -> 46248.375 | I32: =IF($A32="","",IFERROR(IF(INDEX(countries!$I:$I,MATCH($C32,countries!$D:$D,0))=0,$B$12,INDEX(countries!$I:$I,MATCH($C32,countries!$D:$D,0))),$B$12)) -> 72 | J32: =IF($A32="","",$H32-$I32/24) -> 46245.375 | K32: =IF($A32="","",ROUND($J32-NOW(),1)) -> 1.8 | L32: =IF($A32="","",IF($AE32="OVF",IFERROR(INDEX(countries!$G:$G,MATCH($C32,countries!$D:$D,0)),"VERIFY"),IFERROR(INDEX(countries!$H:$H,MATCH($C32,countries!$D:$D,0)),"VERIFY"))) -> REQUIRED | M32: =IF($A32="","",IF(OR(UPPER($G32)="OWN",UPPER($G32)="EXCLUDED"),"CLIENT ARRANGING",IF($K32<0,"OVERDUE",IF($K32<1,"URGENT - FILE NOW",IF($K32<3,"DUE SOON","PENDING"))))) -> DUE SOON | AE32: =IF($A32="","",IF($A32<=COUNTIF(permit_calc!$L$3:$L$144,1),"OVF","LDG")) -> OVF | AF32: =IF($AE32="","",IF($AE32="OVF","",$A32-COUNTIF(permit_calc!$L$3:$L$144,1))) | AH32: =IFERROR(INDEX('PAX & CREW'!$L$3:$L$62,MATCH(ROW()-17,'PAX & CREW'!$AJ$3:$AJ$62,0)),"") | AI32: =IF($AH32="","",IF(COUNTIF($AH$18:$AH32,$AH32)=1,1,0)) | AJ32: =IF($AI32=1,SUM($AI$18:$AI32),"")
A33: =IF(ROW()-29>COUNTIF(permit_calc!$L$3:$L$144,1)+COUNTA($G$18:$G$25),"",ROW()-29) -> 4 | B33: =IF($A33="","",IF($AE33="OVF",INDEX(permit_calc!$B$3:$B$144,MATCH($A33,permit_calc!$N$3:$N$144,0)),IFERROR(INDEX(countries!$B:$B,MATCH($C33,countries!$D:$D,0)),$C33))) -> Angola | C33: {=IF($A33="","",IF($AE33="OVF",INDEX(permit_calc!$A$3:$A$144,MATCH($A33,permit_calc!$N$3:$N$144,0)),INDEX($U$18:$U$25,$AF33)))} -> AGO | D33: =IF($A33="","",$AE33) -> OVF | E33: {=IF($A33="","",IF($AE33="OVF","",INDEX($G$18:$G$25,$AF33)))} | F33: {=IF($A33="","",IF($AE33="OVF",INDEX(permit_calc!$M$3:$M$144,MATCH($A33,permit_calc!$N$3:$N$144,0)),INDEX($A$18:$A$25,$AF33)))} -> L1, L4 | G33: JTL | H33: {=IF($A33="","",IF($AE33="OVF",INDEX($E$18:$E$25,INDEX(permit_calc!$O$3:$O$144,MATCH($A33,permit_calc!$N$3:$N$144,0)))+INDEX($F$18:$F$25,INDEX(permit_calc!$O$3:$O$144,MATCH($A33,permit_calc!$N$3:$N$144,0))),INDEX($L$18:$L$25,$AF33)+INDEX($M$18:$M$25,$AF33)))} -> 46248.375 | I33: =IF($A33="","",IFERROR(IF(INDEX(countries!$I:$I,MATCH($C33,countries!$D:$D,0))=0,$B$12,INDEX(countries!$I:$I,MATCH($C33,countries!$D:$D,0))),$B$12)) -> 72 | J33: =IF($A33="","",$H33-$I33/24) -> 46245.375 | K33: =IF($A33="","",ROUND($J33-NOW(),1)) -> 1.8 | L33: =IF($A33="","",IF($AE33="OVF",IFERROR(INDEX(countries!$G:$G,MATCH($C33,countries!$D:$D,0)),"VERIFY"),IFERROR(INDEX(countries!$H:$H,MATCH($C33,countries!$D:$D,0)),"VERIFY"))) -> REQUIRED | M33: =IF($A33="","",IF(OR(UPPER($G33)="OWN",UPPER($G33)="EXCLUDED"),"CLIENT ARRANGING",IF($K33<0,"OVERDUE",IF($K33<1,"URGENT - FILE NOW",IF($K33<3,"DUE SOON","PENDING"))))) -> DUE SOON | AE33: =IF($A33="","",IF($A33<=COUNTIF(permit_calc!$L$3:$L$144,1),"OVF","LDG")) -> OVF | AF33: =IF($AE33="","",IF($AE33="OVF","",$A33-COUNTIF(permit_calc!$L$3:$L$144,1))) | AH33: =IFERROR(INDEX('PAX & CREW'!$L$3:$L$62,MATCH(ROW()-17,'PAX & CREW'!$AJ$3:$AJ$62,0)),"") | AI33: =IF($AH33="","",IF(COUNTIF($AH$18:$AH33,$AH33)=1,1,0)) | AJ33: =IF($AI33=1,SUM($AI$18:$AI33),"")
A34: =IF(ROW()-29>COUNTIF(permit_calc!$L$3:$L$144,1)+COUNTA($G$18:$G$25),"",ROW()-29) -> 5 | B34: =IF($A34="","",IF($AE34="OVF",INDEX(permit_calc!$B$3:$B$144,MATCH($A34,permit_calc!$N$3:$N$144,0)),IFERROR(INDEX(countries!$B:$B,MATCH($C34,countries!$D:$D,0)),$C34))) -> Democratic Republic of the Congo | C34: {=IF($A34="","",IF($AE34="OVF",INDEX(permit_calc!$A$3:$A$144,MATCH($A34,permit_calc!$N$3:$N$144,0)),INDEX($U$18:$U$25,$AF34)))} -> COD | D34: =IF($A34="","",$AE34) -> OVF | E34: {=IF($A34="","",IF($AE34="OVF","",INDEX($G$18:$G$25,$AF34)))} | F34: {=IF($A34="","",IF($AE34="OVF",INDEX(permit_calc!$M$3:$M$144,MATCH($A34,permit_calc!$N$3:$N$144,0)),INDEX($A$18:$A$25,$AF34)))} -> L1, L4 | G34: JTL | H34: {=IF($A34="","",IF($AE34="OVF",INDEX($E$18:$E$25,INDEX(permit_calc!$O$3:$O$144,MATCH($A34,permit_calc!$N$3:$N$144,0)))+INDEX($F$18:$F$25,INDEX(permit_calc!$O$3:$O$144,MATCH($A34,permit_calc!$N$3:$N$144,0))),INDEX($L$18:$L$25,$AF34)+INDEX($M$18:$M$25,$AF34)))} -> 46248.375 | I34: =IF($A34="","",IFERROR(IF(INDEX(countries!$I:$I,MATCH($C34,countries!$D:$D,0))=0,$B$12,INDEX(countries!$I:$I,MATCH($C34,countries!$D:$D,0))),$B$12)) -> 72 | J34: =IF($A34="","",$H34-$I34/24) -> 46245.375 | K34: =IF($A34="","",ROUND($J34-NOW(),1)) -> 1.8 | L34: =IF($A34="","",IF($AE34="OVF",IFERROR(INDEX(countries!$G:$G,MATCH($C34,countries!$D:$D,0)),"VERIFY"),IFERROR(INDEX(countries!$H:$H,MATCH($C34,countries!$D:$D,0)),"VERIFY"))) -> REQUIRED | M34: =IF($A34="","",IF(OR(UPPER($G34)="OWN",UPPER($G34)="EXCLUDED"),"CLIENT ARRANGING",IF($K34<0,"OVERDUE",IF($K34<1,"URGENT - FILE NOW",IF($K34<3,"DUE SOON","PENDING"))))) -> DUE SOON | AE34: =IF($A34="","",IF($A34<=COUNTIF(permit_calc!$L$3:$L$144,1),"OVF","LDG")) -> OVF | AF34: =IF($AE34="","",IF($AE34="OVF","",$A34-COUNTIF(permit_calc!$L$3:$L$144,1))) | AH34: =IFERROR(INDEX('PAX & CREW'!$L$3:$L$62,MATCH(ROW()-17,'PAX & CREW'!$AJ$3:$AJ$62,0)),"") | AI34: =IF($AH34="","",IF(COUNTIF($AH$18:$AH34,$AH34)=1,1,0)) | AJ34: =IF($AI34=1,SUM($AI$18:$AI34),"")
A35: =IF(ROW()-29>COUNTIF(permit_calc!$L$3:$L$144,1)+COUNTA($G$18:$G$25),"",ROW()-29) -> 6 | B35: =IF($A35="","",IF($AE35="OVF",INDEX(permit_calc!$B$3:$B$144,MATCH($A35,permit_calc!$N$3:$N$144,0)),IFERROR(INDEX(countries!$B:$B,MATCH($C35,countries!$D:$D,0)),$C35))) -> Republic of the Congo | C35: {=IF($A35="","",IF($AE35="OVF",INDEX(permit_calc!$A$3:$A$144,MATCH($A35,permit_calc!$N$3:$N$144,0)),INDEX($U$18:$U$25,$AF35)))} -> COG | D35: =IF($A35="","",$AE35) -> OVF | E35: {=IF($A35="","",IF($AE35="OVF","",INDEX($G$18:$G$25,$AF35)))} | F35: {=IF($A35="","",IF($AE35="OVF",INDEX(permit_calc!$M$3:$M$144,MATCH($A35,permit_calc!$N$3:$N$144,0)),INDEX($A$18:$A$25,$AF35)))} -> L1, L4 | G35: JTL | H35: {=IF($A35="","",IF($AE35="OVF",INDEX($E$18:$E$25,INDEX(permit_calc!$O$3:$O$144,MATCH($A35,permit_calc!$N$3:$N$144,0)))+INDEX($F$18:$F$25,INDEX(permit_calc!$O$3:$O$144,MATCH($A35,permit_calc!$N$3:$N$144,0))),INDEX($L$18:$L$25,$AF35)+INDEX($M$18:$M$25,$AF35)))} -> 46248.375 | I35: =IF($A35="","",IFERROR(IF(INDEX(countries!$I:$I,MATCH($C35,countries!$D:$D,0))=0,$B$12,INDEX(countries!$I:$I,MATCH($C35,countries!$D:$D,0))),$B$12)) -> 72 | J35: =IF($A35="","",$H35-$I35/24) -> 46245.375 | K35: =IF($A35="","",ROUND($J35-NOW(),1)) -> 1.8 | L35: =IF($A35="","",IF($AE35="OVF",IFERROR(INDEX(countries!$G:$G,MATCH($C35,countries!$D:$D,0)),"VERIFY"),IFERROR(INDEX(countries!$H:$H,MATCH($C35,countries!$D:$D,0)),"VERIFY"))) -> REQUIRED | M35: =IF($A35="","",IF(OR(UPPER($G35)="OWN",UPPER($G35)="EXCLUDED"),"CLIENT ARRANGING",IF($K35<0,"OVERDUE",IF($K35<1,"URGENT - FILE NOW",IF($K35<3,"DUE SOON","PENDING"))))) -> DUE SOON | AE35: =IF($A35="","",IF($A35<=COUNTIF(permit_calc!$L$3:$L$144,1),"OVF","LDG")) -> OVF | AF35: =IF($AE35="","",IF($AE35="OVF","",$A35-COUNTIF(permit_calc!$L$3:$L$144,1))) | AH35: =IFERROR(INDEX('PAX & CREW'!$L$3:$L$62,MATCH(ROW()-17,'PAX & CREW'!$AJ$3:$AJ$62,0)),"") | AI35: =IF($AH35="","",IF(COUNTIF($AH$18:$AH35,$AH35)=1,1,0)) | AJ35: =IF($AI35=1,SUM($AI$18:$AI35),"")
A36: =IF(ROW()-29>COUNTIF(permit_calc!$L$3:$L$144,1)+COUNTA($G$18:$G$25),"",ROW()-29) -> 7 | B36: =IF($A36="","",IF($AE36="OVF",INDEX(permit_calc!$B$3:$B$144,MATCH($A36,permit_calc!$N$3:$N$144,0)),IFERROR(INDEX(countries!$B:$B,MATCH($C36,countries!$D:$D,0)),$C36))) -> Central African Republic | C36: {=IF($A36="","",IF($AE36="OVF",INDEX(permit_calc!$A$3:$A$144,MATCH($A36,permit_calc!$N$3:$N$144,0)),INDEX($U$18:$U$25,$AF36)))} -> CAF | D36: =IF($A36="","",$AE36) -> OVF | E36: {=IF($A36="","",IF($AE36="OVF","",INDEX($G$18:$G$25,$AF36)))} | F36: {=IF($A36="","",IF($AE36="OVF",INDEX(permit_calc!$M$3:$M$144,MATCH($A36,permit_calc!$N$3:$N$144,0)),INDEX($A$18:$A$25,$AF36)))} -> L1 | G36: JTL | H36: {=IF($A36="","",IF($AE36="OVF",INDEX($E$18:$E$25,INDEX(permit_calc!$O$3:$O$144,MATCH($A36,permit_calc!$N$3:$N$144,0)))+INDEX($F$18:$F$25,INDEX(permit_calc!$O$3:$O$144,MATCH($A36,permit_calc!$N$3:$N$144,0))),INDEX($L$18:$L$25,$AF36)+INDEX($M$18:$M$25,$AF36)))} -> 46248.375 | I36: =IF($A36="","",IFERROR(IF(INDEX(countries!$I:$I,MATCH($C36,countries!$D:$D,0))=0,$B$12,INDEX(countries!$I:$I,MATCH($C36,countries!$D:$D,0))),$B$12)) -> 72 | J36: =IF($A36="","",$H36-$I36/24) -> 46245.375 | K36: =IF($A36="","",ROUND($J36-NOW(),1)) -> 1.8 | L36: =IF($A36="","",IF($AE36="OVF",IFERROR(INDEX(countries!$G:$G,MATCH($C36,countries!$D:$D,0)),"VERIFY"),IFERROR(INDEX(countries!$H:$H,MATCH($C36,countries!$D:$D,0)),"VERIFY"))) -> REQUIRED | M36: =IF($A36="","",IF(OR(UPPER($G36)="OWN",UPPER($G36)="EXCLUDED"),"CLIENT ARRANGING",IF($K36<0,"OVERDUE",IF($K36<1,"URGENT - FILE NOW",IF($K36<3,"DUE SOON","PENDING"))))) -> DUE SOON | AE36: =IF($A36="","",IF($A36<=COUNTIF(permit_calc!$L$3:$L$144,1),"OVF","LDG")) -> OVF | AF36: =IF($AE36="","",IF($AE36="OVF","",$A36-COUNTIF(permit_calc!$L$3:$L$144,1))) | AH36: =IFERROR(INDEX('PAX & CREW'!$L$3:$L$62,MATCH(ROW()-17,'PAX & CREW'!$AJ$3:$AJ$62,0)),"") | AI36: =IF($AH36="","",IF(COUNTIF($AH$18:$AH36,$AH36)=1,1,0)) | AJ36: =IF($AI36=1,SUM($AI$18:$AI36),"")
A37: =IF(ROW()-29>COUNTIF(permit_calc!$L$3:$L$144,1)+COUNTA($G$18:$G$25),"",ROW()-29) -> 8 | B37: =IF($A37="","",IF($AE37="OVF",INDEX(permit_calc!$B$3:$B$144,MATCH($A37,permit_calc!$N$3:$N$144,0)),IFERROR(INDEX(countries!$B:$B,MATCH($C37,countries!$D:$D,0)),$C37))) -> Libya | C37: {=IF($A37="","",IF($AE37="OVF",INDEX(permit_calc!$A$3:$A$144,MATCH($A37,permit_calc!$N$3:$N$144,0)),INDEX($U$18:$U$25,$AF37)))} -> LBY | D37: =IF($A37="","",$AE37) -> OVF | E37: {=IF($A37="","",IF($AE37="OVF","",INDEX($G$18:$G$25,$AF37)))} | F37: {=IF($A37="","",IF($AE37="OVF",INDEX(permit_calc!$M$3:$M$144,MATCH($A37,permit_calc!$N$3:$N$144,0)),INDEX($A$18:$A$25,$AF37)))} -> L2, L3 | G37: JTL | H37: {=IF($A37="","",IF($AE37="OVF",INDEX($E$18:$E$25,INDEX(permit_calc!$O$3:$O$144,MATCH($A37,permit_calc!$N$3:$N$144,0)))+INDEX($F$18:$F$25,INDEX(permit_calc!$O$3:$O$144,MATCH($A37,permit_calc!$N$3:$N$144,0))),INDEX($L$18:$L$25,$AF37)+INDEX($M$18:$M$25,$AF37)))} -> 46250.25 | I37: =IF($A37="","",IFERROR(IF(INDEX(countries!$I:$I,MATCH($C37,countries!$D:$D,0))=0,$B$12,INDEX(countries!$I:$I,MATCH($C37,countries!$D:$D,0))),$B$12)) -> 72 | J37: =IF($A37="","",$H37-$I37/24) -> 46247.25 | K37: =IF($A37="","",ROUND($J37-NOW(),1)) -> 3.6 | L37: =IF($A37="","",IF($AE37="OVF",IFERROR(INDEX(countries!$G:$G,MATCH($C37,countries!$D:$D,0)),"VERIFY"),IFERROR(INDEX(countries!$H:$H,MATCH($C37,countries!$D:$D,0)),"VERIFY"))) -> REQUIRED | M37: =IF($A37="","",IF(OR(UPPER($G37)="OWN",UPPER($G37)="EXCLUDED"),"CLIENT ARRANGING",IF($K37<0,"OVERDUE",IF($K37<1,"URGENT - FILE NOW",IF($K37<3,"DUE SOON","PENDING"))))) -> PENDING | AE37: =IF($A37="","",IF($A37<=COUNTIF(permit_calc!$L$3:$L$144,1),"OVF","LDG")) -> OVF | AF37: =IF($AE37="","",IF($AE37="OVF","",$A37-COUNTIF(permit_calc!$L$3:$L$144,1))) | AH37: =IFERROR(INDEX('PAX & CREW'!$L$3:$L$62,MATCH(ROW()-17,'PAX & CREW'!$AJ$3:$AJ$62,0)),"") | AI37: =IF($AH37="","",IF(COUNTIF($AH$18:$AH37,$AH37)=1,1,0)) | AJ37: =IF($AI37=1,SUM($AI$18:$AI37),"")
A38: =IF(ROW()-29>COUNTIF(permit_calc!$L$3:$L$144,1)+COUNTA($G$18:$G$25),"",ROW()-29) -> 9 | B38: =IF($A38="","",IF($AE38="OVF",INDEX(permit_calc!$B$3:$B$144,MATCH($A38,permit_calc!$N$3:$N$144,0)),IFERROR(INDEX(countries!$B:$B,MATCH($C38,countries!$D:$D,0)),$C38))) -> Tunisia | C38: {=IF($A38="","",IF($AE38="OVF",INDEX(permit_calc!$A$3:$A$144,MATCH($A38,permit_calc!$N$3:$N$144,0)),INDEX($U$18:$U$25,$AF38)))} -> TUN | D38: =IF($A38="","",$AE38) -> OVF | E38: {=IF($A38="","",IF($AE38="OVF","",INDEX($G$18:$G$25,$AF38)))} | F38: {=IF($A38="","",IF($AE38="OVF",INDEX(permit_calc!$M$3:$M$144,MATCH($A38,permit_calc!$N$3:$N$144,0)),INDEX($A$18:$A$25,$AF38)))} -> L3 | G38: JTL | H38: {=IF($A38="","",IF($AE38="OVF",INDEX($E$18:$E$25,INDEX(permit_calc!$O$3:$O$144,MATCH($A38,permit_calc!$N$3:$N$144,0)))+INDEX($F$18:$F$25,INDEX(permit_calc!$O$3:$O$144,MATCH($A38,permit_calc!$N$3:$N$144,0))),INDEX($L$18:$L$25,$AF38)+INDEX($M$18:$M$25,$AF38)))} -> 46251.167 | I38: =IF($A38="","",IFERROR(IF(INDEX(countries!$I:$I,MATCH($C38,countries!$D:$D,0))=0,$B$12,INDEX(countries!$I:$I,MATCH($C38,countries!$D:$D,0))),$B$12)) -> 72 | J38: =IF($A38="","",$H38-$I38/24) -> 46248.167 | K38: =IF($A38="","",ROUND($J38-NOW(),1)) -> 4.6 | L38: =IF($A38="","",IF($AE38="OVF",IFERROR(INDEX(countries!$G:$G,MATCH($C38,countries!$D:$D,0)),"VERIFY"),IFERROR(INDEX(countries!$H:$H,MATCH($C38,countries!$D:$D,0)),"VERIFY"))) -> REQUIRED | M38: =IF($A38="","",IF(OR(UPPER($G38)="OWN",UPPER($G38)="EXCLUDED"),"CLIENT ARRANGING",IF($K38<0,"OVERDUE",IF($K38<1,"URGENT - FILE NOW",IF($K38<3,"DUE SOON","PENDING"))))) -> PENDING | AE38: =IF($A38="","",IF($A38<=COUNTIF(permit_calc!$L$3:$L$144,1),"OVF","LDG")) -> OVF | AF38: =IF($AE38="","",IF($AE38="OVF","",$A38-COUNTIF(permit_calc!$L$3:$L$144,1)))
A39: =IF(ROW()-29>COUNTIF(permit_calc!$L$3:$L$144,1)+COUNTA($G$18:$G$25),"",ROW()-29) -> 10 | B39: =IF($A39="","",IF($AE39="OVF",INDEX(permit_calc!$B$3:$B$144,MATCH($A39,permit_calc!$N$3:$N$144,0)),IFERROR(INDEX(countries!$B:$B,MATCH($C39,countries!$D:$D,0)),$C39))) -> Algeria | C39: {=IF($A39="","",IF($AE39="OVF",INDEX(permit_calc!$A$3:$A$144,MATCH($A39,permit_calc!$N$3:$N$144,0)),INDEX($U$18:$U$25,$AF39)))} -> DZA | D39: =IF($A39="","",$AE39) -> OVF | E39: {=IF($A39="","",IF($AE39="OVF","",INDEX($G$18:$G$25,$AF39)))} | F39: {=IF($A39="","",IF($AE39="OVF",INDEX(permit_calc!$M$3:$M$144,MATCH($A39,permit_calc!$N$3:$N$144,0)),INDEX($A$18:$A$25,$AF39)))} -> L3, L4 | G39: JTL | H39: {=IF($A39="","",IF($AE39="OVF",INDEX($E$18:$E$25,INDEX(permit_calc!$O$3:$O$144,MATCH($A39,permit_calc!$N$3:$N$144,0)))+INDEX($F$18:$F$25,INDEX(permit_calc!$O$3:$O$144,MATCH($A39,permit_calc!$N$3:$N$144,0))),INDEX($L$18:$L$25,$AF39)+INDEX($M$18:$M$25,$AF39)))} -> 46251.167 | I39: =IF($A39="","",IFERROR(IF(INDEX(countries!$I:$I,MATCH($C39,countries!$D:$D,0))=0,$B$12,INDEX(countries!$I:$I,MATCH($C39,countries!$D:$D,0))),$B$12)) -> 72 | J39: =IF($A39="","",$H39-$I39/24) -> 46248.167 | K39: =IF($A39="","",ROUND($J39-NOW(),1)) -> 4.6 | L39: =IF($A39="","",IF($AE39="OVF",IFERROR(INDEX(countries!$G:$G,MATCH($C39,countries!$D:$D,0)),"VERIFY"),IFERROR(INDEX(countries!$H:$H,MATCH($C39,countries!$D:$D,0)),"VERIFY"))) -> REQUIRED | M39: =IF($A39="","",IF(OR(UPPER($G39)="OWN",UPPER($G39)="EXCLUDED"),"CLIENT ARRANGING",IF($K39<0,"OVERDUE",IF($K39<1,"URGENT - FILE NOW",IF($K39<3,"DUE SOON","PENDING"))))) -> PENDING | AE39: =IF($A39="","",IF($A39<=COUNTIF(permit_calc!$L$3:$L$144,1),"OVF","LDG")) -> OVF | AF39: =IF($AE39="","",IF($AE39="OVF","",$A39-COUNTIF(permit_calc!$L$3:$L$144,1)))
A40: =IF(ROW()-29>COUNTIF(permit_calc!$L$3:$L$144,1)+COUNTA($G$18:$G$25),"",ROW()-29) -> 11 | B40: =IF($A40="","",IF($AE40="OVF",INDEX(permit_calc!$B$3:$B$144,MATCH($A40,permit_calc!$N$3:$N$144,0)),IFERROR(INDEX(countries!$B:$B,MATCH($C40,countries!$D:$D,0)),$C40))) -> Mali | C40: {=IF($A40="","",IF($AE40="OVF",INDEX(permit_calc!$A$3:$A$144,MATCH($A40,permit_calc!$N$3:$N$144,0)),INDEX($U$18:$U$25,$AF40)))} -> MLI | D40: =IF($A40="","",$AE40) -> OVF | E40: {=IF($A40="","",IF($AE40="OVF","",INDEX($G$18:$G$25,$AF40)))} | F40: {=IF($A40="","",IF($AE40="OVF",INDEX(permit_calc!$M$3:$M$144,MATCH($A40,permit_calc!$N$3:$N$144,0)),INDEX($A$18:$A$25,$AF40)))} -> L4 | G40: JTL | H40: {=IF($A40="","",IF($AE40="OVF",INDEX($E$18:$E$25,INDEX(permit_calc!$O$3:$O$144,MATCH($A40,permit_calc!$N$3:$N$144,0)))+INDEX($F$18:$F$25,INDEX(permit_calc!$O$3:$O$144,MATCH($A40,permit_calc!$N$3:$N$144,0))),INDEX($L$18:$L$25,$AF40)+INDEX($M$18:$M$25,$AF40)))} -> 46253.042 | I40: =IF($A40="","",IFERROR(IF(INDEX(countries!$I:$I,MATCH($C40,countries!$D:$D,0))=0,$B$12,INDEX(countries!$I:$I,MATCH($C40,countries!$D:$D,0))),$B$12)) -> 72 | J40: =IF($A40="","",$H40-$I40/24) -> 46250.042 | K40: =IF($A40="","",ROUND($J40-NOW(),1)) -> 6.4 | L40: =IF($A40="","",IF($AE40="OVF",IFERROR(INDEX(countries!$G:$G,MATCH($C40,countries!$D:$D,0)),"VERIFY"),IFERROR(INDEX(countries!$H:$H,MATCH($C40,countries!$D:$D,0)),"VERIFY"))) -> REQUIRED | M40: =IF($A40="","",IF(OR(UPPER($G40)="OWN",UPPER($G40)="EXCLUDED"),"CLIENT ARRANGING",IF($K40<0,"OVERDUE",IF($K40<1,"URGENT - FILE NOW",IF($K40<3,"DUE SOON","PENDING"))))) -> PENDING | AE40: =IF($A40="","",IF($A40<=COUNTIF(permit_calc!$L$3:$L$144,1),"OVF","LDG")) -> OVF | AF40: =IF($AE40="","",IF($AE40="OVF","",$A40-COUNTIF(permit_calc!$L$3:$L$144,1)))
A41: =IF(ROW()-29>COUNTIF(permit_calc!$L$3:$L$144,1)+COUNTA($G$18:$G$25),"",ROW()-29) -> 12 | B41: =IF($A41="","",IF($AE41="OVF",INDEX(permit_calc!$B$3:$B$144,MATCH($A41,permit_calc!$N$3:$N$144,0)),IFERROR(INDEX(countries!$B:$B,MATCH($C41,countries!$D:$D,0)),$C41))) -> Niger | C41: {=IF($A41="","",IF($AE41="OVF",INDEX(permit_calc!$A$3:$A$144,MATCH($A41,permit_calc!$N$3:$N$144,0)),INDEX($U$18:$U$25,$AF41)))} -> NER | D41: =IF($A41="","",$AE41) -> OVF | E41: {=IF($A41="","",IF($AE41="OVF","",INDEX($G$18:$G$25,$AF41)))} | F41: {=IF($A41="","",IF($AE41="OVF",INDEX(permit_calc!$M$3:$M$144,MATCH($A41,permit_calc!$N$3:$N$144,0)),INDEX($A$18:$A$25,$AF41)))} -> L4 | G41: JTL | H41: {=IF($A41="","",IF($AE41="OVF",INDEX($E$18:$E$25,INDEX(permit_calc!$O$3:$O$144,MATCH($A41,permit_calc!$N$3:$N$144,0)))+INDEX($F$18:$F$25,INDEX(permit_calc!$O$3:$O$144,MATCH($A41,permit_calc!$N$3:$N$144,0))),INDEX($L$18:$L$25,$AF41)+INDEX($M$18:$M$25,$AF41)))} -> 46253.042 | I41: =IF($A41="","",IFERROR(IF(INDEX(countries!$I:$I,MATCH($C41,countries!$D:$D,0))=0,$B$12,INDEX(countries!$I:$I,MATCH($C41,countries!$D:$D,0))),$B$12)) -> 72 | J41: =IF($A41="","",$H41-$I41/24) -> 46250.042 | K41: =IF($A41="","",ROUND($J41-NOW(),1)) -> 6.4 | L41: =IF($A41="","",IF($AE41="OVF",IFERROR(INDEX(countries!$G:$G,MATCH($C41,countries!$D:$D,0)),"VERIFY"),IFERROR(INDEX(countries!$H:$H,MATCH($C41,countries!$D:$D,0)),"VERIFY"))) -> REQUIRED | M41: =IF($A41="","",IF(OR(UPPER($G41)="OWN",UPPER($G41)="EXCLUDED"),"CLIENT ARRANGING",IF($K41<0,"OVERDUE",IF($K41<1,"URGENT - FILE NOW",IF($K41<3,"DUE SOON","PENDING"))))) -> PENDING | AE41: =IF($A41="","",IF($A41<=COUNTIF(permit_calc!$L$3:$L$144,1),"OVF","LDG")) -> OVF | AF41: =IF($AE41="","",IF($AE41="OVF","",$A41-COUNTIF(permit_calc!$L$3:$L$144,1)))
A42: =IF(ROW()-29>COUNTIF(permit_calc!$L$3:$L$144,1)+COUNTA($G$18:$G$25),"",ROW()-29) -> 13 | B42: =IF($A42="","",IF($AE42="OVF",INDEX(permit_calc!$B$3:$B$144,MATCH($A42,permit_calc!$N$3:$N$144,0)),IFERROR(INDEX(countries!$B:$B,MATCH($C42,countries!$D:$D,0)),$C42))) -> Nigeria | C42: {=IF($A42="","",IF($AE42="OVF",INDEX(permit_calc!$A$3:$A$144,MATCH($A42,permit_calc!$N$3:$N$144,0)),INDEX($U$18:$U$25,$AF42)))} -> NGA | D42: =IF($A42="","",$AE42) -> OVF | E42: {=IF($A42="","",IF($AE42="OVF","",INDEX($G$18:$G$25,$AF42)))} | F42: {=IF($A42="","",IF($AE42="OVF",INDEX(permit_calc!$M$3:$M$144,MATCH($A42,permit_calc!$N$3:$N$144,0)),INDEX($A$18:$A$25,$AF42)))} -> L4 | G42: JTL | H42: {=IF($A42="","",IF($AE42="OVF",INDEX($E$18:$E$25,INDEX(permit_calc!$O$3:$O$144,MATCH($A42,permit_calc!$N$3:$N$144,0)))+INDEX($F$18:$F$25,INDEX(permit_calc!$O$3:$O$144,MATCH($A42,permit_calc!$N$3:$N$144,0))),INDEX($L$18:$L$25,$AF42)+INDEX($M$18:$M$25,$AF42)))} -> 46253.042 | I42: =IF($A42="","",IFERROR(IF(INDEX(countries!$I:$I,MATCH($C42,countries!$D:$D,0))=0,$B$12,INDEX(countries!$I:$I,MATCH($C42,countries!$D:$D,0))),$B$12)) -> 72 | J42: =IF($A42="","",$H42-$I42/24) -> 46250.042 | K42: =IF($A42="","",ROUND($J42-NOW(),1)) -> 6.4 | L42: =IF($A42="","",IF($AE42="OVF",IFERROR(INDEX(countries!$G:$G,MATCH($C42,countries!$D:$D,0)),"VERIFY"),IFERROR(INDEX(countries!$H:$H,MATCH($C42,countries!$D:$D,0)),"VERIFY"))) -> REQUIRED | M42: =IF($A42="","",IF(OR(UPPER($G42)="OWN",UPPER($G42)="EXCLUDED"),"CLIENT ARRANGING",IF($K42<0,"OVERDUE",IF($K42<1,"URGENT - FILE NOW",IF($K42<3,"DUE SOON","PENDING"))))) -> PENDING | AE42: =IF($A42="","",IF($A42<=COUNTIF(permit_calc!$L$3:$L$144,1),"OVF","LDG")) -> OVF | AF42: =IF($AE42="","",IF($AE42="OVF","",$A42-COUNTIF(permit_calc!$L$3:$L$144,1)))
...

Sheet admin
A1: Workstation UTC offset (hrs) | B1: 0
A2: Document root path | B2: C:\Backups\InsiderTechSol\Aviation\Jetelio_v3\.LAYOUT\resources
A3: Reference lists
A4: Airport Type | B4: PPR Required | C4: Location Type | D4: Airport of Entry | E4: Fuel Types | F4: Vendor Category
A5: Civil | B5: Yes | C5: Airport | D5: Yes | E5: JET A-1 | F5: Handler
A6: Military | B6: No | C6: Airstrip | D6: No | E6: AVGAS | F6: Permit
A7: Private | B7: Prior Notice | C7: Helipad | D7: Seasonal | E7: JET A-1 + AVGAS | F7: Supervisor
A8: Joint | C8: Bulk Origin | E8: None | F8: Fuel
A9: Other | C9: Bulk Destination | F9: Catering
C10: Shipping Port | F10: Security
C11: Aircraft Carrier | F11: Transport
C12: Other | F12: Other
A14: OPERATIONAL DEFAULTS — single source of truth for every fallback
A15: Default permit lead time (hrs) — FALLBACK ONLY, not a verified figure | B15: 72
A16: Default ground service notice (hrs) | B16: 24
A17: Range reserve / safety margin (fraction of max range) | B17: 0.15
A18: Passport validity buffer beyond trip end (days) | B18: 180
A19: Document expiry alert thresholds (days before expiry) | B19: 180, 90, 30, 7
A20: Visa rule staleness limit (days since verified) | B20: 365
A21: Unverified reference data may be used for planning? | B21: NO

Sheet airports
A1: IDENTIFIERS | E1: LOCATION & CONTACT | N1: GEO & TIME | W1: OPERATIONS | AE1: INFRASTRUCTURE | AJ1: LIVE DATA | AM1: BULLETINS | AO1: DOCUMENTS | AS1: RELATED RECORDS | AU1: OTHER
A2: Airport ICAO | B2: Airport IATA | C2: FAA ID | D2: EIP ICAO | E2: Airport Name | F2: Location Type | G2: Airport Type | H2: Country | I2: City Name | J2: Location / Region | K2: Airport Address 1 | L2: Airport Address 2 | M2: Website | N2: Coordinates (DMS) | O2: Latitude (DD) | P2: Longitude (DD) | Q2: Elevation (m) | R2: Elevation (ft) | S2: Magnetic Variation | T2: Time Zone | U2: UTC Offset (hrs) | V2: Local Time (now) | W2: Airport Hours | X2: Operating Hours | Y2: Airport of Entry | Z2: PPR Required | AA2: CIQ Procedure | AB2: Arrival Slot | AC2: Departure Slot | AD2: Approaches | AE2: Runway(s) | AF2: PCN No. | AG2: Fuel Types Available | AH2: Security Rating | AI2: Alternates | AJ2: NOTAM | AK2: Airport OFP | AL2: Daily Weather | AM2: Country Bulletin | AN2: City Bulletin | AO2: Airport Charts (folder) | AP2: Runway Diagram | AQ2: Airport Images | AR2: City Map | AS2: VISA Info | AT2: Vendors | AU2: Strategic Role | AV2: Last Updated | AW2: ops_data_source | AX2: ops_data_verified_on | AY2: tech_stop_readiness
