Workbook

Sheet Collector
A1: AFRICA — OVERFLIGHT & LANDING PERMIT FEES AND ANCILLARY AIR NAVIGATION CHARGES
A2: All 54 African states. Fee columns require verification against current CAA circulars / trip-support rate sheets before operational use.
A4: Country | B4: ICAO Prefix | C4: Sub-Region | D4: ANSP / FIR Authority | E4: ASECNA Member | F4: VSAT Network | G4: O/F Permit Req'd | H4: Landing Permit Req'd | I4: Lead Time (working days) | J4: Permit Validity | K4: O/F Permit Fee (per leg, as published) | L4: Landing Permit Fee (as published) | M4: En-Route Charge Basis | N4: VSAT / Comms Charge | O4: NAFISAT / AFISNET Charge | P4: Other Fees & Notes | Q4: Source Status
A5: Algeria | B5: DA | C5: North Africa | D5: ENNA | E5: No | F5: NAFISAT | G5: Yes | H5: Yes | I5: 3-5 | J5: +72 hrs | K5: None | M5: National unit rate x distance x sqrt(MTOW/50) | N5: Recovered within en-route bill — rate not published | O5: NAFISAT surcharge — billed with en-route charge, rate not published | P5: CAA permit fee and en-route unit rate published only in national AIP GEN 4 / AIC — obtain current circular. | Q5: NOT VERIFIED — no official published rate located
A6: Angola | B6: FN | C6: Southern Africa | D6: ENANA | E6: No | F6: SADC VSAT | G6: Yes | H6: Yes | I6: 5-7 | J6: +72 hrs | K6: None | M6: National unit rate x distance x sqrt(MTOW/50) | N6: Recovered within en-route bill — rate not published | O6: n/a | P6: CAA permit fee and en-route unit rate published only in national AIP GEN 4 / AIC — obtain current circular. | Q6: NOT VERIFIED — no official published rate located
A7: Benin | B7: DB | C7: West Africa | D7: ASECNA | E7: Yes | F7: AFISNET | G7: Yes | H7: Yes | I7: 2-3 | J7: +72 hrs | K7: 120 | L7: 120 | M7: ASECNA: unit charge x coefficient — see calculator rows 61-91 | N7: Recovered within en-route bill — rate not published | O7: AFISNET surcharge — billed with en-route charge, rate not published | P7: CAA overflight/landing permit fee is an administrative charge — not published in AIP; obtain from CAA or handler. En-route billed by ASECNA. | Q7: ASECNA eAIP GEN 4.3 (eff. 28 DEC 2023) — OFFICIAL
A8: Botswana | B8: FB | C8: Southern Africa | D8: CAAB | E8: No | F8: SADC VSAT | G8: Yes | H8: Yes | I8: 2-3 | J8: +72 hrs | K8: None | M8: National unit rate x distance x sqrt(MTOW/50) | N8: Recovered within en-route bill — rate not published | O8: n/a | P8: CAA permit fee and en-route unit rate published only in national AIP GEN 4 / AIC — obtain current circular. | Q8: NOT VERIFIED — no official published rate located
A9: Burkina Faso | B9: DF | C9: West Africa | D9: ASECNA | E9: Yes | F9: AFISNET | G9: Yes | H9: Yes | I9: 2-3 | J9: +72 hrs | K9: None | M9: ASECNA: unit charge x coefficient — see calculator rows 61-91 | N9: Recovered within en-route bill — rate not published | O9: AFISNET surcharge — billed with en-route charge, rate not published | P9: CAA overflight/landing permit fee is an administrative charge — not published in AIP; obtain from CAA or handler. En-route billed by ASECNA. | Q9: ASECNA eAIP GEN 4.3 (eff. 28 DEC 2023) — OFFICIAL
A10: Burundi | B10: HB | C10: East Africa | D10: AACB | E10: No | F10: - | G10: Yes | H10: Yes | I10: 3-5 | J10: +72 hrs | K10: 50 | M10: National unit rate x distance x sqrt(MTOW/50) | N10: n/a | O10: n/a | P10: CAA permit fee and en-route unit rate published only in national AIP GEN 4 / AIC — obtain current circular. | Q10: NOT VERIFIED — no official published rate located
A11: Cabo Verde | B11: GV | C11: West Africa | D11: ASA / AAC | E11: No | F11: - | G11: Yes | H11: Yes | I11: 2-3 | J11: +72 hrs | K11: None | M11: National unit rate x distance x sqrt(MTOW/50) | N11: n/a | O11: n/a | P11: CAA permit fee and en-route unit rate published only in national AIP GEN 4 / AIC — obtain current circular. | Q11: NOT VERIFIED — no official published rate located
A12: Cameroon | B12: FK | C12: Central Africa | D12: ASECNA | E12: Yes | F12: AFISNET | G12: Yes | H12: Yes | I12: 3-5 | J12: +72 hrs | K12: None | M12: ASECNA: unit charge x coefficient — see calculator rows 61-91 | N12: Recovered within en-route bill — rate not published | O12: AFISNET surcharge — billed with en-route charge, rate not published | P12: CCAA development licence fee: XAF 15,000 per aircraft + XAF 10,000 per passenger (UN aircraft exempt) | Q12: ASECNA eAIP GEN 4.3 (eff. 28 DEC 2023) — OFFICIAL
A13: Central African Republic | B13: FE | C13: Central Africa | D13: ASECNA | E13: Yes | F13: AFISNET | G13: Yes | H13: Yes | I13: 3-5 | J13: +24 hrs | K13: EUR 72 (std, 72h) / EUR 228 (urgent, 24h) / EUR 440 (top urgent, 1h) | M13: ASECNA: unit charge x coefficient — see calculator rows 61-91 | N13: Recovered within en-route bill — rate not published | O13: AFISNET surcharge — billed with en-route charge, rate not published | P13: CAA overflight/landing permit fee is an administrative charge — not published in AIP; obtain from CAA or handler. En-route billed by ASECNA. | Q13: ASECNA eAIP GEN 4.3 (eff. 28 DEC 2023) — OFFICIAL
A14: Chad | B14: FT | C14: Central Africa | D14: ASECNA | E14: Yes | F14: NAFISAT | G14: Yes | H14: Yes | I14: 3-5 | J14: +72 hrs | K14: None | M14: ASECNA: unit charge x coefficient — see calculator rows 61-91 | N14: Recovered within en-route bill — rate not published | O14: NAFISAT surcharge — billed with en-route charge, rate not published | P14: CAA overflight/landing permit fee is an administrative charge — not published in AIP; obtain from CAA or handler. En-route billed by ASECNA. | Q14: ASECNA eAIP GEN 4.3 (eff. 28 DEC 2023) — OFFICIAL
A15: Comoros | B15: FM | C15: East Africa | D15: ASECNA | E15: Yes | F15: - | G15: Yes | H15: Yes | I15: 3-5 | J15: +72 hrs | K15: EUR 150 | M15: ASECNA: unit charge x coefficient — see calculator rows 61-91 | N15: n/a | O15: n/a | P15: CAA overflight/landing permit fee is an administrative charge — not published in AIP; obtain from CAA or handler. En-route billed by ASECNA. | Q15: ASECNA eAIP GEN 4.3 (eff. 28 DEC 2023) — OFFICIAL
A16: Congo (Republic of) | B16: FC | C16: Central Africa | D16: ASECNA | E16: Yes | F16: AFISNET | G16: Yes | H16: Yes | I16: 3-5 | J16: Verify | K16: Not found | M16: ASECNA: unit charge x coefficient — see calculator rows 61-91 | N16: Recovered within en-route bill — rate not published | O16: AFISNET surcharge — billed with en-route charge, rate not published | P16: CAA overflight/landing permit fee is an administrative charge — not published in AIP; obtain from CAA or handler. En-route billed by ASECNA. | Q16: ASECNA eAIP GEN 4.3 (eff. 28 DEC 2023) — OFFICIAL
A17: Congo (DRC) | B17: FZ | C17: Central Africa | D17: RVA | E17: No | F17: SADC VSAT | G17: Yes | H17: Yes | I17: 5-7 | J17: +72 hrs | K17: None | M17: National unit rate x distance x sqrt(MTOW/50) | N17: Recovered within en-route bill — rate not published | O17: n/a | P17: CAA permit fee and en-route unit rate published only in national AIP GEN 4 / AIC — obtain current circular. | Q17: NOT VERIFIED — no official published rate located
A18: Côte d'Ivoire | B18: DI | C18: West Africa | D18: ASECNA | E18: Yes | F18: AFISNET | G18: Yes | H18: Yes | I18: 3-5 | J18: +72 hrs | K18: 200 | M18: ASECNA: unit charge x coefficient — see calculator rows 61-91 | N18: Recovered within en-route bill — rate not published | O18: AFISNET surcharge — billed with en-route charge, rate not published | P18: CAA overflight/landing permit fee is an administrative charge — not published in AIP; obtain from CAA or handler. En-route billed by ASECNA. | Q18: ASECNA eAIP GEN 4.3 (eff. 28 DEC 2023) — OFFICIAL
A19: Djibouti | B19: HD | C19: East Africa | D19: DCAA | E19: No | F19: NAFISAT | G19: Yes | H19: Yes | I19: 3-5 | J19: +72 hrs | K19: None | M19: National unit rate x distance x sqrt(MTOW/50) | N19: Recovered within en-route bill — rate not published | O19: NAFISAT surcharge — billed with en-route charge, rate not published | P19: CAA permit fee and en-route unit rate published only in national AIP GEN 4 / AIC — obtain current circular. | Q19: NOT VERIFIED — no official published rate located
A20: Egypt | B20: HE | C20: North Africa | D20: NANSC | E20: No | F20: NAFISAT | G20: Yes | H20: Yes | I20: 4-7 | J20: +24 hrs | K20: None | M20: National unit rate x distance x sqrt(MTOW/50) | N20: Recovered within en-route bill — rate not published | O20: NAFISAT surcharge — billed with en-route charge, rate not published | P20: CAA permit fee and en-route unit rate published only in national AIP GEN 4 / AIC — obtain current circular. | Q20: NOT VERIFIED — no official published rate located
A21: Equatorial Guinea | B21: FG | C21: Central Africa | D21: ASECNA | E21: Yes | F21: AFISNET | G21: Yes | H21: Yes | I21: 5-7 | J21: +72 hrs | K21: None | M21: ASECNA: unit charge x coefficient — see calculator rows 61-91 | N21: Recovered within en-route bill — rate not published | O21: AFISNET surcharge — billed with en-route charge, rate not published | P21: CAA overflight/landing permit fee is an administrative charge — not published in AIP; obtain from CAA or handler. En-route billed by ASECNA. | Q21: ASECNA eAIP GEN 4.3 (eff. 28 DEC 2023) — OFFICIAL
A22: Eritrea | B22: HH | C22: East Africa | D22: ECAA | E22: No | F22: - | G22: Yes | H22: Yes | I22: 7-10 | J22: +72 hrs | K22: None | M22: National unit rate x distance x sqrt(MTOW/50) | N22: n/a | O22: n/a | P22: CAA permit fee and en-route unit rate published only in national AIP GEN 4 / AIC — obtain current circular. | Q22: NOT VERIFIED — no official published rate located
A23: Eswatini | B23: FD | C23: Southern Africa | D23: ESWACAA | E23: No | F23: SADC VSAT | G23: Yes | H23: Yes | I23: 3-5 | J23: +72 hrs | K23: None | M23: National unit rate x distance x sqrt(MTOW/50) | N23: Recovered within en-route bill — rate not published | O23: n/a | P23: CAA permit fee and en-route unit rate published only in national AIP GEN 4 / AIC — obtain current circular. | Q23: NOT VERIFIED — no official published rate located
A24: Ethiopia | B24: HA | C24: East Africa | D24: ECAA | E24: No | F24: NAFISAT | G24: Yes | H24: Yes | I24: 3-5 | J24: +72 hrs | K24: 40 | M24: National unit rate x distance x sqrt(MTOW/50) | N24: Recovered within en-route bill — rate not published | O24: NAFISAT surcharge — billed with en-route charge, rate not published | P24: CAA permit fee and en-route unit rate published only in national AIP GEN 4 / AIC — obtain current circular. | Q24: NOT VERIFIED — no official published rate located
A25: Gabon | B25: FO | C25: Central Africa | D25: ASECNA | E25: Yes | F25: AFISNET | G25: Yes | H25: Yes | I25: 3-5 | J25: +48 hrs | K25: 275 | M25: ASECNA: unit charge x coefficient — see calculator rows 61-91 | N25: Recovered within en-route bill — rate not published | O25: AFISNET surcharge — billed with en-route charge, rate not published | P25: CAA overflight/landing permit fee is an administrative charge — not published in AIP; obtain from CAA or handler. En-route billed by ASECNA. | Q25: ASECNA eAIP GEN 4.3 (eff. 28 DEC 2023) — OFFICIAL
A26: Gambia | B26: GB | C26: West Africa | D26: GCAA | E26: No | F26: AFISNET | G26: Yes | H26: Yes | I26: 2-3 | J26: +72 hrs | K26: None | M26: National unit rate x distance x sqrt(MTOW/50) | N26: Recovered within en-route bill — rate not published | O26: AFISNET surcharge — billed with en-route charge, rate not published | P26: CAA permit fee and en-route unit rate published only in national AIP GEN 4 / AIC — obtain current circular. | Q26: NOT VERIFIED — no official published rate located
A27: Ghana | B27: DG | C27: West Africa | D27: GCAA | E27: No | F27: AFISNET | G27: Yes | H27: Yes | I27: 3-5 | J27: Date/time specific | K27: 150 | L27: 150 | M27: National unit rate x distance x sqrt(MTOW/50) | N27: Recovered within en-route bill — rate not published | O27: AFISNET surcharge — billed with en-route charge, rate not published | P27: CAA permit fee and en-route unit rate published only in national AIP GEN 4 / AIC — obtain current circular. | Q27: NOT VERIFIED — no official published rate located
A28: Guinea | B28: GU | C28: West Africa | D28: AGNA | E28: No | F28: AFISNET | G28: Yes | H28: Yes | I28: 3-5 | J28: +72 hrs | K28: None | M28: National unit rate x distance x sqrt(MTOW/50) | N28: Recovered within en-route bill — rate not published | O28: AFISNET surcharge — billed with en-route charge, rate not published | P28: CAA permit fee and en-route unit rate published only in national AIP GEN 4 / AIC — obtain current circular. | Q28: NOT VERIFIED — no official published rate located
A29: Guinea-Bissau | B29: GG | C29: West Africa | D29: ASECNA | E29: Yes | F29: AFISNET | G29: Yes | H29: Yes | I29: 3-5 | J29: +72 hrs | K29: None | M29: ASECNA: unit charge x coefficient — see calculator rows 61-91 | N29: Recovered within en-route bill — rate not published | O29: AFISNET surcharge — billed with en-route charge, rate not published | P29: CAA overflight/landing permit fee is an administrative charge — not published in AIP; obtain from CAA or handler. En-route billed by ASECNA. | Q29: ASECNA eAIP GEN 4.3 (eff. 28 DEC 2023) — OFFICIAL
A30: Kenya | B30: HK | C30: East Africa | D30: KCAA | E30: No | F30: - | G30: Yes | H30: Yes | I30: 3-5 | J30: +72 hrs | K30: 50 | M30: National unit rate x distance x sqrt(MTOW/50) | N30: n/a | O30: n/a | P30: CAA permit fee and en-route unit rate published only in national AIP GEN 4 / AIC — obtain current circular. | Q30: NOT VERIFIED — no official published rate located
A31: Lesotho | B31: FX | C31: Southern Africa | D31: LDCA | E31: No | F31: SADC VSAT | G31: Yes | H31: Yes | I31: 3-5 | J31: +72 hrs | K31: None | M31: National unit rate x distance x sqrt(MTOW/50) | N31: Recovered within en-route bill — rate not published | O31: n/a | P31: CAA permit fee and en-route unit rate published only in national AIP GEN 4 / AIC — obtain current circular. | Q31: NOT VERIFIED — no official published rate located
A32: Liberia | B32: GL | C32: West Africa | D32: LCAA | E32: No | F32: AFISNET | G32: Yes | H32: Yes | I32: 3-5 | J32: +72 hrs | K32: None | M32: National unit rate x distance x sqrt(MTOW/50) | N32: Recovered within en-route bill — rate not published | O32: AFISNET surcharge — billed with en-route charge, rate not published | P32: CAA permit fee and en-route unit rate published only in national AIP GEN 4 / AIC — obtain current circular. | Q32: NOT VERIFIED — no official published rate located
A33: Libya | B33: HL | C33: North Africa | D33: LYCAA | E33: No | F33: NAFISAT | G33: Yes | H33: Yes | I33: 7-10 | J33: +72 hrs | K33: 11 | M33: National unit rate x distance x sqrt(MTOW/50) | N33: Recovered within en-route bill — rate not published | O33: NAFISAT surcharge — billed with en-route charge, rate not published | P33: CAA permit fee and en-route unit rate published only in national AIP GEN 4 / AIC — obtain current circular. | Q33: NOT VERIFIED — no official published rate located
A34: Madagascar | B34: FM | C34: East Africa | D34: ASECNA | E34: Yes | F34: - | G34: Yes | H34: Yes | I34: 3-5 | J34: +72 hrs | K34: None | M34: ASECNA: unit charge x coefficient — see calculator rows 61-91 | N34: n/a | O34: n/a | P34: CAA overflight/landing permit fee is an administrative charge — not published in AIP; obtain from CAA or handler. En-route billed by ASECNA. | Q34: ASECNA eAIP GEN 4.3 (eff. 28 DEC 2023) — OFFICIAL
A35: Malawi | B35: FW | C35: Southern Africa | D35: DCA | E35: No | F35: SADC VSAT | G35: Yes | H35: Yes | I35: 3-5 | J35: +72 hrs | K35: None | M35: National unit rate x distance x sqrt(MTOW/50) | N35: Recovered within en-route bill — rate not published | O35: n/a | P35: CAA permit fee and en-route unit rate published only in national AIP GEN 4 / AIC — obtain current circular. | Q35: NOT VERIFIED — no official published rate located
A36: Mali | B36: GA | C36: West Africa | D36: ASECNA | E36: Yes | F36: NAFISAT | G36: Yes | H36: Yes | I36: 3-5 | J36: +72 hrs | K36: None | M36: ASECNA: unit charge x coefficient — see calculator rows 61-91 | N36: Recovered within en-route bill — rate not published | O36: NAFISAT surcharge — billed with en-route charge, rate not published | P36: CAA overflight/landing permit fee is an administrative charge — not published in AIP; obtain from CAA or handler. En-route billed by ASECNA. | Q36: ASECNA eAIP GEN 4.3 (eff. 28 DEC 2023) — OFFICIAL
A37: Mauritania | B37: GQ | C37: West Africa | D37: ASECNA | E37: Yes | F37: NAFISAT | G37: Yes | H37: Yes | I37: 3-5 | J37: +24 hrs | K37: None | M37: ASECNA: unit charge x coefficient — see calculator rows 61-91 | N37: Recovered within en-route bill — rate not published | O37: NAFISAT surcharge — billed with en-route charge, rate not published | P37: CAA overflight/landing permit fee is an administrative charge — not published in AIP; obtain from CAA or handler. En-route billed by ASECNA. | Q37: ASECNA eAIP GEN 4.3 (eff. 28 DEC 2023) — OFFICIAL
A38: Mauritius | B38: FI | C38: East Africa | D38: DCA | E38: No | F38: - | G38: Yes | H38: Yes | I38: 3-5 | J38: +72 hrs | K38: None | M38: National unit rate x distance x sqrt(MTOW/50) | N38: n/a | O38: n/a | P38: CAA permit fee and en-route unit rate published only in national AIP GEN 4 / AIC — obtain current circular. | Q38: NOT VERIFIED — no official published rate located
A39: Morocco | B39: GM | C39: North Africa | D39: ONDA | E39: No | F39: NAFISAT | G39: Yes | H39: Yes | I39: 3-5 | J39: +24 hrs | K39: None | M39: National unit rate x distance x sqrt(MTOW/50) | N39: Recovered within en-route bill — rate not published | O39: NAFISAT surcharge — billed with en-route charge, rate not published | P39: CAA permit fee and en-route unit rate published only in national AIP GEN 4 / AIC — obtain current circular. | Q39: NOT VERIFIED — no official published rate located
A40: Mozambique | B40: FQ | C40: Southern Africa | D40: IACM / ADM | E40: No | F40: SADC VSAT | G40: Yes | H40: Yes | I40: 5-7 | J40: +72 hrs | K40: None | M40: National unit rate x distance x sqrt(MTOW/50) | N40: Recovered within en-route bill — rate not published | O40: n/a | P40: CAA permit fee and en-route unit rate published only in national AIP GEN 4 / AIC — obtain current circular. | Q40: NOT VERIFIED — no official published rate located
A41: Namibia | B41: FY | C41: Southern Africa | D41: NCAA | E41: No | F41: SADC VSAT | G41: Yes | H41: Yes | I41: 2-3 | J41: +72 hrs | K41: None | M41: National unit rate x distance x sqrt(MTOW/50) | N41: Recovered within en-route bill — rate not published | O41: n/a | P41: CAA permit fee and en-route unit rate published only in national AIP GEN 4 / AIC — obtain current circular. | Q41: NOT VERIFIED — no official published rate located
...

Sheet IAS
A1: AFRICA — FEE MATRIX BY COUNTRY AND FEE TYPE
A3: Country | B3: CAA O/F Permit Fee ($) | C3: CAA Landing Permit Fee ($) | D3: Urgent / Short-Notice Permit Fee ($) | E3: ASECNA Unit Charge >14t Intl ($) | F3: ASECNA Flat Charge <14t Intl ($) | G3: SADC VSAT Charge ($/ FIR crossing) | H3: NAFISAT Charge ($/ FIR crossing) | I3: AFISNET Charge | J3: National En-Route Charge Basis | K3: Other Statutory Fees | L3: OUR Overfly Fee ($) | M3: OUR Landing Permit Fee ($) | N3: OUR STO Volume-Based Fee ($) | O3: TOTAL OVERFLY FEES ($) | P3: TOTAL LANDING FEES ($)
A4: =Collector!A5 -> Algeria | B4: 0 | C4: 0 | D4: 20 | E4: =IF(Collector!E5="Yes",Collector!$D$64*$D$68,0) -> 0 | F4: =IF(Collector!E5="Yes",Collector!$D$66*$D$68,0) -> 0 | G4: =IF(Collector!F5="SADC VSAT",$D$61,0) -> 0 | H4: =IF(Collector!F5="NAFISAT",$D$62,0) -> 10 | I4: =IF(Collector!F5="AFISNET",$D$63,"n/a") -> n/a | J4: =Collector!M5 -> National unit rate x distance x sqrt(MTOW/50) | K4: =IF(Collector!P5="","—",Collector!P5) -> CAA permit fee and en-route unit rate published only in national AIP GEN 4 / AIC — obtain current circular. | L4: =$D$74 -> 50 | M4: =$D$75 -> 100 | N4: =$D$76 -> 40 | O4: =B4+E4+F4+G4+H4+L4 -> 60 | P4: =C4+E4+F4+G4+H4+M4 -> 110
A5: =Collector!A6 -> Angola | B5: 0 | C5: 0 | D5: 20 | E5: =IF(Collector!E6="Yes",Collector!$D$64*$D$68,0) -> 0 | F5: =IF(Collector!E6="Yes",Collector!$D$66*$D$68,0) -> 0 | G5: =IF(Collector!F6="SADC VSAT",$D$61,0) -> 9.6 | H5: =IF(Collector!F6="NAFISAT",$D$62,0) -> 0 | I5: =IF(Collector!F6="AFISNET",$D$63,"n/a") -> n/a | J5: =Collector!M6 -> National unit rate x distance x sqrt(MTOW/50) | K5: =IF(Collector!P6="","—",Collector!P6) -> CAA permit fee and en-route unit rate published only in national AIP GEN 4 / AIC — obtain current circular. | L5: =$D$74 -> 50 | M5: =$D$75 -> 100 | N5: =$D$76 -> 40 | O5: =B5+E5+F5+G5+H5+L5 -> 59.6 | P5: =C5+E5+F5+G5+H5+M5 -> 109.6
A6: =Collector!A7 -> Benin | B6: 120 | C6: 120 | D6: 20 | E6: =IF(Collector!E7="Yes",Collector!$D$64*$D$68,0) -> 122.29812 | F6: =IF(Collector!E7="Yes",Collector!$D$66*$D$68,0) -> 244.60779 | G6: =IF(Collector!F7="SADC VSAT",$D$61,0) -> 0 | H6: =IF(Collector!F7="NAFISAT",$D$62,0) -> 0 | I6: =IF(Collector!F7="AFISNET",$D$63,"n/a") -> Not published separately | J6: =Collector!M7 -> ASECNA: unit charge x coefficient — see calculator rows 61-91 | K6: =IF(Collector!P7="","—",Collector!P7) -> CAA overflight/landing permit fee is an administrative charge — not published in AIP; obtain from CAA or handler. En-route billed by ASECNA. | L6: =$D$74 -> 50 | M6: =$D$75 -> 100 | N6: =$D$76 -> 40 | O6: =B6+E6+F6+G6+H6+L6 -> 536.90591 | P6: =C6+E6+F6+G6+H6+M6 -> 586.90591
A7: =Collector!A8 -> Botswana | B7: 0 | C7: 0 | D7: 20 | E7: =IF(Collector!E8="Yes",Collector!$D$64*$D$68,0) -> 0 | F7: =IF(Collector!E8="Yes",Collector!$D$66*$D$68,0) -> 0 | G7: =IF(Collector!F8="SADC VSAT",$D$61,0) -> 9.6 | H7: =IF(Collector!F8="NAFISAT",$D$62,0) -> 0 | I7: =IF(Collector!F8="AFISNET",$D$63,"n/a") -> n/a | J7: =Collector!M8 -> National unit rate x distance x sqrt(MTOW/50) | K7: =IF(Collector!P8="","—",Collector!P8) -> CAA permit fee and en-route unit rate published only in national AIP GEN 4 / AIC — obtain current circular. | L7: =$D$74 -> 50 | M7: =$D$75 -> 100 | N7: =$D$76 -> 40 | O7: =B7+E7+F7+G7+H7+L7 -> 59.6 | P7: =C7+E7+F7+G7+H7+M7 -> 109.6
A8: =Collector!A9 -> Burkina Faso | B8: 0 | C8: 0 | D8: 20 | E8: =IF(Collector!E9="Yes",Collector!$D$64*$D$68,0) -> 122.29812 | F8: =IF(Collector!E9="Yes",Collector!$D$66*$D$68,0) -> 244.60779 | G8: =IF(Collector!F9="SADC VSAT",$D$61,0) -> 0 | H8: =IF(Collector!F9="NAFISAT",$D$62,0) -> 0 | I8: =IF(Collector!F9="AFISNET",$D$63,"n/a") -> Not published separately | J8: =Collector!M9 -> ASECNA: unit charge x coefficient — see calculator rows 61-91 | K8: =IF(Collector!P9="","—",Collector!P9) -> CAA overflight/landing permit fee is an administrative charge — not published in AIP; obtain from CAA or handler. En-route billed by ASECNA. | L8: =$D$74 -> 50 | M8: =$D$75 -> 100 | N8: =$D$76 -> 40 | O8: =B8+E8+F8+G8+H8+L8 -> 416.90591 | P8: =C8+E8+F8+G8+H8+M8 -> 466.90591
A9: =Collector!A10 -> Burundi | B9: 30 | C9: 50 | D9: 20 | E9: =IF(Collector!E10="Yes",Collector!$D$64*$D$68,0) -> 0 | F9: =IF(Collector!E10="Yes",Collector!$D$66*$D$68,0) -> 0 | G9: =IF(Collector!F10="SADC VSAT",$D$61,0) -> 0 | H9: =IF(Collector!F10="NAFISAT",$D$62,0) -> 0 | I9: =IF(Collector!F10="AFISNET",$D$63,"n/a") -> n/a | J9: =Collector!M10 -> National unit rate x distance x sqrt(MTOW/50) | K9: =IF(Collector!P10="","—",Collector!P10) -> CAA permit fee and en-route unit rate published only in national AIP GEN 4 / AIC — obtain current circular. | L9: =$D$74 -> 50 | M9: =$D$75 -> 100 | N9: =$D$76 -> 40 | O9: =B9+E9+F9+G9+H9+L9 -> 80 | P9: =C9+E9+F9+G9+H9+M9 -> 150
A10: =Collector!A11 -> Cabo Verde | B10: 0 | C10: 0 | D10: 20 | E10: =IF(Collector!E11="Yes",Collector!$D$64*$D$68,0) -> 0 | F10: =IF(Collector!E11="Yes",Collector!$D$66*$D$68,0) -> 0 | G10: =IF(Collector!F11="SADC VSAT",$D$61,0) -> 0 | H10: =IF(Collector!F11="NAFISAT",$D$62,0) -> 0 | I10: =IF(Collector!F11="AFISNET",$D$63,"n/a") -> n/a | J10: =Collector!M11 -> National unit rate x distance x sqrt(MTOW/50) | K10: =IF(Collector!P11="","—",Collector!P11) -> CAA permit fee and en-route unit rate published only in national AIP GEN 4 / AIC — obtain current circular. | L10: =$D$74 -> 50 | M10: =$D$75 -> 100 | N10: =$D$76 -> 40 | O10: =B10+E10+F10+G10+H10+L10 -> 50 | P10: =C10+E10+F10+G10+H10+M10 -> 100
A11: =Collector!A12 -> Cameroon | B11: 0 | C11: 0 | D11: 20 | E11: =IF(Collector!E12="Yes",Collector!$D$64*$D$68,0) -> 122.29812 | F11: =IF(Collector!E12="Yes",Collector!$D$66*$D$68,0) -> 244.60779 | G11: =IF(Collector!F12="SADC VSAT",$D$61,0) -> 0 | H11: =IF(Collector!F12="NAFISAT",$D$62,0) -> 0 | I11: =IF(Collector!F12="AFISNET",$D$63,"n/a") -> Not published separately | J11: =Collector!M12 -> ASECNA: unit charge x coefficient — see calculator rows 61-91 | K11: =IF(Collector!P12="","—",Collector!P12) -> CCAA development licence fee: XAF 15,000 per aircraft + XAF 10,000 per passenger (UN aircraft exempt) | L11: =$D$74 -> 50 | M11: =$D$75 -> 100 | N11: =$D$76 -> 40 | O11: =B11+E11+F11+G11+H11+L11 -> 416.90591 | P11: =C11+E11+F11+G11+H11+M11 -> 466.90591
A12: =Collector!A13 -> Central African Republic | B12: =72*$D$68 -> 83.196 | C12: 0 | D12: =228*$D$68 -> 263.454 | E12: =IF(Collector!E13="Yes",Collector!$D$64*$D$68,0) -> 122.29812 | F12: =IF(Collector!E13="Yes",Collector!$D$66*$D$68,0) -> 244.60779 | G12: =IF(Collector!F13="SADC VSAT",$D$61,0) -> 0 | H12: =IF(Collector!F13="NAFISAT",$D$62,0) -> 0 | I12: =IF(Collector!F13="AFISNET",$D$63,"n/a") -> Not published separately | J12: =Collector!M13 -> ASECNA: unit charge x coefficient — see calculator rows 61-91 | K12: =IF(Collector!P13="","—",Collector!P13) -> CAA overflight/landing permit fee is an administrative charge — not published in AIP; obtain from CAA or handler. En-route billed by ASECNA. | L12: =$D$74 -> 50 | M12: =$D$75 -> 100 | N12: =$D$76 -> 40 | O12: =B12+E12+F12+G12+H12+L12 -> 500.10191 | P12: =C12+E12+F12+G12+H12+M12 -> 466.90591
A13: =Collector!A14 -> Chad | B13: 20 | C13: 20 | D13: 20 | E13: =IF(Collector!E14="Yes",Collector!$D$64*$D$68,0) -> 122.29812 | F13: =IF(Collector!E14="Yes",Collector!$D$66*$D$68,0) -> 244.60779 | G13: =IF(Collector!F14="SADC VSAT",$D$61,0) -> 0 | H13: =IF(Collector!F14="NAFISAT",$D$62,0) -> 10 | I13: =IF(Collector!F14="AFISNET",$D$63,"n/a") -> n/a | J13: =Collector!M14 -> ASECNA: unit charge x coefficient — see calculator rows 61-91 | K13: =IF(Collector!P14="","—",Collector!P14) -> CAA overflight/landing permit fee is an administrative charge — not published in AIP; obtain from CAA or handler. En-route billed by ASECNA. | L13: =$D$74 -> 50 | M13: =$D$75 -> 100 | N13: =$D$76 -> 40 | O13: =B13+E13+F13+G13+H13+L13 -> 446.90591 | P13: =C13+E13+F13+G13+H13+M13 -> 496.90591
A14: =Collector!A15 -> Comoros | B14: =150*$D$68 -> 173.325 | C14: =150*$D$68 -> 173.325 | D14: 50 | E14: =IF(Collector!E15="Yes",Collector!$D$64*$D$68,0) -> 122.29812 | F14: =IF(Collector!E15="Yes",Collector!$D$66*$D$68,0) -> 244.60779 | G14: =IF(Collector!F15="SADC VSAT",$D$61,0) -> 0 | H14: =IF(Collector!F15="NAFISAT",$D$62,0) -> 0 | I14: =IF(Collector!F15="AFISNET",$D$63,"n/a") -> n/a | J14: =Collector!M15 -> ASECNA: unit charge x coefficient — see calculator rows 61-91 | K14: =IF(Collector!P15="","—",Collector!P15) -> CAA overflight/landing permit fee is an administrative charge — not published in AIP; obtain from CAA or handler. En-route billed by ASECNA. | L14: =$D$74 -> 50 | M14: =$D$75 -> 100 | N14: =$D$76 -> 40 | O14: =B14+E14+F14+G14+H14+L14 -> 590.23091 | P14: =C14+E14+F14+G14+H14+M14 -> 640.23091
A15: =Collector!A16 -> Congo (Republic of) | B15: 0 | C15: 0 | D15: 50 | E15: =IF(Collector!E16="Yes",Collector!$D$64*$D$68,0) -> 122.29812 | F15: =IF(Collector!E16="Yes",Collector!$D$66*$D$68,0) -> 244.60779 | G15: =IF(Collector!F16="SADC VSAT",$D$61,0) -> 0 | H15: =IF(Collector!F16="NAFISAT",$D$62,0) -> 0 | I15: =IF(Collector!F16="AFISNET",$D$63,"n/a") -> Not published separately | J15: =Collector!M16 -> ASECNA: unit charge x coefficient — see calculator rows 61-91 | K15: =IF(Collector!P16="","—",Collector!P16) -> CAA overflight/landing permit fee is an administrative charge — not published in AIP; obtain from CAA or handler. En-route billed by ASECNA. | L15: =$D$74 -> 50 | M15: =$D$75 -> 100 | N15: =$D$76 -> 40 | O15: =B15+E15+F15+G15+H15+L15 -> 416.90591 | P15: =C15+E15+F15+G15+H15+M15 -> 466.90591
A16: =Collector!A17 -> Congo (DRC) | B16: 50 | C16: 250 | D16: 100 | E16: =IF(Collector!E17="Yes",Collector!$D$64*$D$68,0) -> 0 | F16: =IF(Collector!E17="Yes",Collector!$D$66*$D$68,0) -> 0 | G16: =IF(Collector!F17="SADC VSAT",$D$61,0) -> 9.6 | H16: =IF(Collector!F17="NAFISAT",$D$62,0) -> 0 | I16: =IF(Collector!F17="AFISNET",$D$63,"n/a") -> n/a | J16: =Collector!M17 -> National unit rate x distance x sqrt(MTOW/50) | K16: =IF(Collector!P17="","—",Collector!P17) -> CAA permit fee and en-route unit rate published only in national AIP GEN 4 / AIC — obtain current circular. | L16: =$D$74 -> 50 | M16: =$D$75 -> 100 | N16: =$D$76 -> 40 | O16: =B16+E16+F16+G16+H16+L16 -> 109.6 | P16: =C16+E16+F16+G16+H16+M16 -> 359.6
A17: =Collector!A18 -> Côte d'Ivoire | B17: 20 | C17: 200 | D17: 20 | E17: =IF(Collector!E18="Yes",Collector!$D$64*$D$68,0) -> 122.29812 | F17: =IF(Collector!E18="Yes",Collector!$D$66*$D$68,0) -> 244.60779 | G17: =IF(Collector!F18="SADC VSAT",$D$61,0) -> 0 | H17: =IF(Collector!F18="NAFISAT",$D$62,0) -> 0 | I17: =IF(Collector!F18="AFISNET",$D$63,"n/a") -> Not published separately | J17: =Collector!M18 -> ASECNA: unit charge x coefficient — see calculator rows 61-91 | K17: =IF(Collector!P18="","—",Collector!P18) -> CAA overflight/landing permit fee is an administrative charge — not published in AIP; obtain from CAA or handler. En-route billed by ASECNA. | L17: =$D$74 -> 50 | M17: =$D$75 -> 100 | N17: =$D$76 -> 40 | O17: =B17+E17+F17+G17+H17+L17 -> 436.90591 | P17: =C17+E17+F17+G17+H17+M17 -> 666.90591
A18: =Collector!A19 -> Djibouti | B18: 20 | C18: 20 | D18: 20 | E18: =IF(Collector!E19="Yes",Collector!$D$64*$D$68,0) -> 0 | F18: =IF(Collector!E19="Yes",Collector!$D$66*$D$68,0) -> 0 | G18: =IF(Collector!F19="SADC VSAT",$D$61,0) -> 0 | H18: =IF(Collector!F19="NAFISAT",$D$62,0) -> 10 | I18: =IF(Collector!F19="AFISNET",$D$63,"n/a") -> n/a | J18: =Collector!M19 -> National unit rate x distance x sqrt(MTOW/50) | K18: =IF(Collector!P19="","—",Collector!P19) -> CAA permit fee and en-route unit rate published only in national AIP GEN 4 / AIC — obtain current circular. | L18: =$D$74 -> 50 | M18: =$D$75 -> 100 | N18: =$D$76 -> 40 | O18: =B18+E18+F18+G18+H18+L18 -> 80 | P18: =C18+E18+F18+G18+H18+M18 -> 130
A19: =Collector!A20 -> Egypt | B19: 20 | C19: 20 | D19: 0 | E19: =IF(Collector!E20="Yes",Collector!$D$64*$D$68,0) -> 0 | F19: =IF(Collector!E20="Yes",Collector!$D$66*$D$68,0) -> 0 | G19: =IF(Collector!F20="SADC VSAT",$D$61,0) -> 0 | H19: =IF(Collector!F20="NAFISAT",$D$62,0) -> 10 | I19: =IF(Collector!F20="AFISNET",$D$63,"n/a") -> n/a | J19: =Collector!M20 -> National unit rate x distance x sqrt(MTOW/50) | K19: =IF(Collector!P20="","—",Collector!P20) -> CAA permit fee and en-route unit rate published only in national AIP GEN 4 / AIC — obtain current circular. | L19: =$D$74 -> 50 | M19: =$D$75 -> 100 | N19: =$D$76 -> 40 | O19: =B19+E19+F19+G19+H19+L19 -> 80 | P19: =C19+E19+F19+G19+H19+M19 -> 130
A20: =Collector!A21 -> Equatorial Guinea | B20: 80 | C20: 100 | D20: 20 | E20: =IF(Collector!E21="Yes",Collector!$D$64*$D$68,0) -> 122.29812 | F20: =IF(Collector!E21="Yes",Collector!$D$66*$D$68,0) -> 244.60779 | G20: =IF(Collector!F21="SADC VSAT",$D$61,0) -> 0 | H20: =IF(Collector!F21="NAFISAT",$D$62,0) -> 0 | I20: =IF(Collector!F21="AFISNET",$D$63,"n/a") -> Not published separately | J20: =Collector!M21 -> ASECNA: unit charge x coefficient — see calculator rows 61-91 | K20: =IF(Collector!P21="","—",Collector!P21) -> CAA overflight/landing permit fee is an administrative charge — not published in AIP; obtain from CAA or handler. En-route billed by ASECNA. | L20: =$D$74 -> 50 | M20: =$D$75 -> 100 | N20: =$D$76 -> 40 | O20: =B20+E20+F20+G20+H20+L20 -> 496.90591 | P20: =C20+E20+F20+G20+H20+M20 -> 566.90591
A21: =Collector!A22 -> Eritrea | B21: 230 | C21: 230 | D21: 20 | E21: =IF(Collector!E22="Yes",Collector!$D$64*$D$68,0) -> 0 | F21: =IF(Collector!E22="Yes",Collector!$D$66*$D$68,0) -> 0 | G21: =IF(Collector!F22="SADC VSAT",$D$61,0) -> 0 | H21: =IF(Collector!F22="NAFISAT",$D$62,0) -> 0 | I21: =IF(Collector!F22="AFISNET",$D$63,"n/a") -> n/a | J21: =Collector!M22 -> National unit rate x distance x sqrt(MTOW/50) | K21: =IF(Collector!P22="","—",Collector!P22) -> CAA permit fee and en-route unit rate published only in national AIP GEN 4 / AIC — obtain current circular. | L21: =$D$74 -> 50 | M21: =$D$75 -> 100 | N21: =$D$76 -> 40 | O21: =B21+E21+F21+G21+H21+L21 -> 280 | P21: =C21+E21+F21+G21+H21+M21 -> 330
A22: =Collector!A23 -> Eswatini | B22: 0 | C22: 0 | D22: 20 | E22: =IF(Collector!E23="Yes",Collector!$D$64*$D$68,0) -> 0 | F22: =IF(Collector!E23="Yes",Collector!$D$66*$D$68,0) -> 0 | G22: =IF(Collector!F23="SADC VSAT",$D$61,0) -> 9.6 | H22: =IF(Collector!F23="NAFISAT",$D$62,0) -> 0 | I22: =IF(Collector!F23="AFISNET",$D$63,"n/a") -> n/a | J22: =Collector!M23 -> National unit rate x distance x sqrt(MTOW/50) | K22: =IF(Collector!P23="","—",Collector!P23) -> CAA permit fee and en-route unit rate published only in national AIP GEN 4 / AIC — obtain current circular. | L22: =$D$74 -> 50 | M22: =$D$75 -> 100 | N22: =$D$76 -> 40 | O22: =B22+E22+F22+G22+H22+L22 -> 59.6 | P22: =C22+E22+F22+G22+H22+M22 -> 109.6
A23: =Collector!A24 -> Ethiopia | B23: 40 | C23: 40 | D23: 20 | E23: =IF(Collector!E24="Yes",Collector!$D$64*$D$68,0) -> 0 | F23: =IF(Collector!E24="Yes",Collector!$D$66*$D$68,0) -> 0 | G23: =IF(Collector!F24="SADC VSAT",$D$61,0) -> 0 | H23: =IF(Collector!F24="NAFISAT",$D$62,0) -> 10 | I23: =IF(Collector!F24="AFISNET",$D$63,"n/a") -> n/a | J23: =Collector!M24 -> National unit rate x distance x sqrt(MTOW/50) | K23: =IF(Collector!P24="","—",Collector!P24) -> CAA permit fee and en-route unit rate published only in national AIP GEN 4 / AIC — obtain current circular. | L23: =$D$74 -> 50 | M23: =$D$75 -> 100 | N23: =$D$76 -> 40 | O23: =B23+E23+F23+G23+H23+L23 -> 100 | P23: =C23+E23+F23+G23+H23+M23 -> 150
A24: =Collector!A25 -> Gabon | B24: 275 | C24: 275 | D24: 20 | E24: =IF(Collector!E25="Yes",Collector!$D$64*$D$68,0) -> 122.29812 | F24: =IF(Collector!E25="Yes",Collector!$D$66*$D$68,0) -> 244.60779 | G24: =IF(Collector!F25="SADC VSAT",$D$61,0) -> 0 | H24: =IF(Collector!F25="NAFISAT",$D$62,0) -> 0 | I24: =IF(Collector!F25="AFISNET",$D$63,"n/a") -> Not published separately | J24: =Collector!M25 -> ASECNA: unit charge x coefficient — see calculator rows 61-91 | K24: =IF(Collector!P25="","—",Collector!P25) -> CAA overflight/landing permit fee is an administrative charge — not published in AIP; obtain from CAA or handler. En-route billed by ASECNA. | L24: =$D$74 -> 50 | M24: =$D$75 -> 100 | N24: =$D$76 -> 40 | O24: =B24+E24+F24+G24+H24+L24 -> 691.90591 | P24: =C24+E24+F24+G24+H24+M24 -> 741.90591
A25: =Collector!A26 -> Gambia | B25: 0 | C25: 0 | D25: 20 | E25: =IF(Collector!E26="Yes",Collector!$D$64*$D$68,0) -> 0 | F25: =IF(Collector!E26="Yes",Collector!$D$66*$D$68,0) -> 0 | G25: =IF(Collector!F26="SADC VSAT",$D$61,0) -> 0 | H25: =IF(Collector!F26="NAFISAT",$D$62,0) -> 0 | I25: =IF(Collector!F26="AFISNET",$D$63,"n/a") -> Not published separately | J25: =Collector!M26 -> National unit rate x distance x sqrt(MTOW/50) | K25: =IF(Collector!P26="","—",Collector!P26) -> CAA permit fee and en-route unit rate published only in national AIP GEN 4 / AIC — obtain current circular. | L25: =$D$74 -> 50 | M25: =$D$75 -> 100 | N25: =$D$76 -> 40 | O25: =B25+E25+F25+G25+H25+L25 -> 50 | P25: =C25+E25+F25+G25+H25+M25 -> 100
A26: =Collector!A27 -> Ghana | B26: 150 | C26: 150 | D26: 20 | E26: =IF(Collector!E27="Yes",Collector!$D$64*$D$68,0) -> 0 | F26: =IF(Collector!E27="Yes",Collector!$D$66*$D$68,0) -> 0 | G26: =IF(Collector!F27="SADC VSAT",$D$61,0) -> 0 | H26: =IF(Collector!F27="NAFISAT",$D$62,0) -> 0 | I26: =IF(Collector!F27="AFISNET",$D$63,"n/a") -> Not published separately | J26: =Collector!M27 -> National unit rate x distance x sqrt(MTOW/50) | K26: =IF(Collector!P27="","—",Collector!P27) -> CAA permit fee and en-route unit rate published only in national AIP GEN 4 / AIC — obtain current circular. | L26: =$D$74 -> 50 | M26: =$D$75 -> 100 | N26: =$D$76 -> 40 | O26: =B26+E26+F26+G26+H26+L26 -> 200 | P26: =C26+E26+F26+G26+H26+M26 -> 250
... A40: =Collector!A41 -> Namibia | B40: 0 | C40: 0 | D40: 20 | E40: =IF(Collector!E41="Yes",Collector!$D$64*$D$68,0) -> 0 | F40: =IF(Collector!E41="Yes",Collector!$D$66*$D$68,0) -> 0 | G40: =IF(Collector!F41="SADC VSAT",$D$61,0) -> 9.6 | H40: =IF(Collector!F41="NAFISAT",$D$62,0) -> 0 | I40: =IF(Collector!F41="AFISNET",$D$63,"n/a") -> n/a | J40: =Collector!M41 -> National unit rate x distance x sqrt(MTOW/50) | K40: =IF(Collector!P41="","—",Collector!P41) -> CAA permit fee and en-route unit rate published only in national AIP GEN 4 / AIC — obtain current circular. | L40: =$D$74 -> 50 | M40: =$D$75 -> 100 | N40: =$D$76 -> 40 | O40: =B40+E40+F40+G40+H40+L40 -> 59.6 | P40: =C40+E40+F40+G40+H40+M40 -> 109.6
A41: =Collector!A42 -> Niger | B41: =70*$D$68 -> 80.885 | C41: 0 | D41: 50 | E41: =IF(Collector!E42="Yes",Collector!$D$64*$D$68,0) -> 122.29812 | F41: =IF(Collector!E42="Yes",Collector!$D$66*$D$68,0) -> 244.60779 | G41: =IF(Collector!F42="SADC VSAT",$D$61,0) -> 0 | H41: =IF(Collector!F42="NAFISAT",$D$62,0) -> 10 | I41: =IF(Collector!F42="AFISNET",$D$63,"n/a") -> n/a | J41: =Collector!M42 -> ASECNA: unit charge x coefficient — see calculator rows 61-91 | K41: =IF(Collector!P42="","—",Collector!P42) -> CAA overflight/landing permit fee is an administrative charge — not published in AIP; obtain from CAA or handler. En-route billed by ASECNA. | L41: =$D$74 -> 50 | M41: =$D$75 -> 100 | N41: =$D$76 -> 40 | O41: =B41+E41+F41+G41+H41+L41 -> 507.79091 | P41: =C41+E41+F41+G41+H41+M41 -> 476.90591
A42: =Collector!A43 -> Nigeria | B42: 50 | C42: 50 | D42: 50 | E42: =IF(Collector!E43="Yes",Collector!$D$64*$D$68,0) -> 0 | F42: =IF(Collector!E43="Yes",Collector!$D$66*$D$68,0) -> 0 | G42: =IF(Collector!F43="SADC VSAT",$D$61,0) -> 0 | H42: =IF(Collector!F43="NAFISAT",$D$62,0) -> 10 | I42: =IF(Collector!F43="AFISNET",$D$63,"n/a") -> n/a | J42: =Collector!M43 -> National unit rate x distance x sqrt(MTOW/50) | K42: =IF(Collector!P43="","—",Collector!P43) -> CAA permit fee and en-route unit rate published only in national AIP GEN 4 / AIC — obtain current circular. | L42: =$D$74 -> 50 | M42: =$D$75 -> 100 | N42: =$D$76 -> 40 | O42: =B42+E42+F42+G42+H42+L42 -> 110 | P42: =C42+E42+F42+G42+H42+M42 -> 160
A43: =Collector!A44 -> Rwanda | B43: 500 | C43: 500 | D43: 50 | E43: =IF(Collector!E44="Yes",Collector!$D$64*$D$68,0) -> 0 | F43: =IF(Collector!E44="Yes",Collector!$D$66*$D$68,0) -> 0 | G43: =IF(Collector!F44="SADC VSAT",$D$61,0) -> 0 | H43: =IF(Collector!F44="NAFISAT",$D$62,0) -> 0 | I43: =IF(Collector!F44="AFISNET",$D$63,"n/a") -> n/a | J43: =Collector!M44 -> National unit rate x distance x sqrt(MTOW/50) | K43: =IF(Collector!P44="","—",Collector!P44) -> CAA permit fee and en-route unit rate published only in national AIP GEN 4 / AIC — obtain current circular. | L43: =$D$74 -> 50 | M43: =$D$75 -> 100 | N43: =$D$76 -> 40 | O43: =B43+E43+F43+G43+H43+L43 -> 550 | P43: =C43+E43+F43+G43+H43+M43 -> 600
A44: =Collector!A45 -> São Tomé and Príncipe | B44: 115 | C44: 0 | D44: 50 | E44: =IF(Collector!E45="Yes",Collector!$D$64*$D$68,0) -> 0 | F44: =IF(Collector!E45="Yes",Collector!$D$66*$D$68,0) -> 0 | G44: =IF(Collector!F45="SADC VSAT",$D$61,0) -> 0 | H44: =IF(Collector!F45="NAFISAT",$D$62,0) -> 0 | I44: =IF(Collector!F45="AFISNET",$D$63,"n/a") -> Not published separately | J44: =Collector!M45 -> National unit rate x distance x sqrt(MTOW/50) | K44: =IF(Collector!P45="","—",Collector!P45) -> CAA permit fee and en-route unit rate published only in national AIP GEN 4 / AIC — obtain current circular. | L44: =$D$74 -> 50 | M44: =$D$75 -> 100 | N44: =$D$76 -> 40 | O44: =B44+E44+F44+G44+H44+L44 -> 165 | P44: =C44+E44+F44+G44+H44+M44 -> 100
A45: =Collector!A46 -> Senegal | B45: 50 | C45: 50 | D45: 20 | E45: =IF(Collector!E46="Yes",Collector!$D$64*$D$68,0) -> 122.29812 | F45: =IF(Collector!E46="Yes",Collector!$D$66*$D$68,0) -> 244.60779 | G45: =IF(Collector!F46="SADC VSAT",$D$61,0) -> 0 | H45: =IF(Collector!F46="NAFISAT",$D$62,0) -> 0 | I45: =IF(Collector!F46="AFISNET",$D$63,"n/a") -> Not published separately | J45: =Collector!M46 -> ASECNA: unit charge x coefficient — see calculator rows 61-91 | K45: =IF(Collector!P46="","—",Collector!P46) -> CAA overflight/landing permit fee is an administrative charge — not published in AIP; obtain from CAA or handler. En-route billed by ASECNA. | L45: =$D$74 -> 50 | M45: =$D$75 -> 100 | N45: =$D$76 -> 40 | O45: =B45+E45+F45+G45+H45+L45 -> 466.90591 | P45: =C45+E45+F45+G45+H45+M45 -> 516.90591
A46: =Collector!A47 -> Seychelles | B46: 0 | C46: 0 | D46: 20 | E46: =IF(Collector!E47="Yes",Collector!$D$64*$D$68,0) -> 0 | F46: =IF(Collector!E47="Yes",Collector!$D$66*$D$68,0) -> 0 | G46: =IF(Collector!F47="SADC VSAT",$D$61,0) -> 0 | H46: =IF(Collector!F47="NAFISAT",$D$62,0) -> 0 | I46: =IF(Collector!F47="AFISNET",$D$63,"n/a") -> n/a | J46: =Collector!M47 -> National unit rate x distance x sqrt(MTOW/50) | K46: =IF(Collector!P47="","—",Collector!P47) -> CAA permit fee and en-route unit rate published only in national AIP GEN 4 / AIC — obtain current circular. | L46: =$D$74 -> 50 | M46: =$D$75 -> 100 | N46: =$D$76 -> 40 | O46: =B46+E46+F46+G46+H46+L46 -> 50 | P46: =C46+E46+F46+G46+H46+M46 -> 100
A47: =Collector!A48 -> Sierra Leone | B47: 50 | C47: 50 | D47: 20 | E47: =IF(Collector!E48="Yes",Collector!$D$64*$D$68,0) -> 0 | F47: =IF(Collector!E48="Yes",Collector!$D$66*$D$68,0) -> 0 | G47: =IF(Collector!F48="SADC VSAT",$D$61,0) -> 0 | H47: =IF(Collector!F48="NAFISAT",$D$62,0) -> 0 | I47: =IF(Collector!F48="AFISNET",$D$63,"n/a") -> Not published separately | J47: =Collector!M48 -> National unit rate x distance x sqrt(MTOW/50) | K47: =IF(Collector!P48="","—",Collector!P48) -> CAA permit fee and en-route unit rate published only in national AIP GEN 4 / AIC — obtain current circular. | L47: =$D$74 -> 50 | M47: =$D$75 -> 100 | N47: =$D$76 -> 40 | O47: =B47+E47+F47+G47+H47+L47 -> 100 | P47: =C47+E47+F47+G47+H47+M47 -> 150
A48: =Collector!A49 -> Somalia | B48: 0 | C48: 0 | D48: 20 | E48: =IF(Collector!E49="Yes",Collector!$D$64*$D$68,0) -> 0 | F48: =IF(Collector!E49="Yes",Collector!$D$66*$D$68,0) -> 0 | G48: =IF(Collector!F49="SADC VSAT",$D$61,0) -> 0 | H48: =IF(Collector!F49="NAFISAT",$D$62,0) -> 0 | I48: =IF(Collector!F49="AFISNET",$D$63,"n/a") -> n/a | J48: =Collector!M49 -> Flat en-route charge per crossing (FIR) | K48: =IF(Collector!P49="","—",Collector!P49) -> CAA permit fee and en-route unit rate published only in national AIP GEN 4 / AIC — obtain current circular. | L48: =$D$74 -> 50 | M48: =$D$75 -> 100 | N48: =$D$76 -> 40 | O48: =B48+E48+F48+G48+H48+L48 -> 50 | P48: =C48+E48+F48+G48+H48+M48 -> 100
A49: =Collector!A50 -> South Africa | B49: 0 | C49: 0 | D49: 100 | E49: =IF(Collector!E50="Yes",Collector!$D$64*$D$68,0) -> 0 | F49: =IF(Collector!E50="Yes",Collector!$D$66*$D$68,0) -> 0 | G49: =IF(Collector!F50="SADC VSAT",$D$61,0) -> 9.6 | H49: =IF(Collector!F50="NAFISAT",$D$62,0) -> 0 | I49: =IF(Collector!F50="AFISNET",$D$63,"n/a") -> n/a | J49: =Collector!M50 -> National unit rate x distance x sqrt(MTOW/50) | K49: =IF(Collector!P50="","—",Collector!P50) -> CAA permit fee and en-route unit rate published only in national AIP GEN 4 / AIC — obtain current circular. | L49: =$D$74 -> 50 | M49: =$D$75 -> 100 | N49: =$D$76 -> 40 | O49: =B49+E49+F49+G49+H49+L49 -> 59.6 | P49: =C49+E49+F49+G49+H49+M49 -> 109.6
A50: =Collector!A51 -> South Sudan | B50: 60 | C50: 60 | D50: 20 | E50: =IF(Collector!E51="Yes",Collector!$D$64*$D$68,0) -> 0 | F50: =IF(Collector!E51="Yes",Collector!$D$66*$D$68,0) -> 0 | G50: =IF(Collector!F51="SADC VSAT",$D$61,0) -> 0 | H50: =IF(Collector!F51="NAFISAT",$D$62,0) -> 10 | I50: =IF(Collector!F51="AFISNET",$D$63,"n/a") -> n/a | J50: =Collector!M51 -> National unit rate x distance x sqrt(MTOW/50) | K50: =IF(Collector!P51="","—",Collector!P51) -> CAA permit fee and en-route unit rate published only in national AIP GEN 4 / AIC — obtain current circular. | L50: =$D$74 -> 50 | M50: =$D$75 -> 100 | N50: =$D$76 -> 40 | O50: =B50+E50+F50+G50+H50+L50 -> 120 | P50: =C50+E50+F50+G50+H50+M50 -> 170
A51: =Collector!A52 -> Sudan | B51: =750*$D$69 -> 927.225 | C51: =750*$D$69 -> 927.225 | D51: 100 | E51: =IF(Collector!E52="Yes",Collector!$D$64*$D$68,0) -> 0 | F51: =IF(Collector!E52="Yes",Collector!$D$66*$D$68,0) -> 0 | G51: =IF(Collector!F52="SADC VSAT",$D$61,0) -> 0 | H51: =IF(Collector!F52="NAFISAT",$D$62,0) -> 10 | I51: =IF(Collector!F52="AFISNET",$D$63,"n/a") -> n/a | J51: =Collector!M52 -> National unit rate x distance x sqrt(MTOW/50) | K51: =IF(Collector!P52="","—",Collector!P52) -> CAA permit fee and en-route unit rate published only in national AIP GEN 4 / AIC — obtain current circular. | L51: =$D$74 -> 50 | M51: =$D$75 -> 100 | N51: =$D$76 -> 40 | O51: =B51+E51+F51+G51+H51+L51 -> 987.225 | P51: =C51+E51+F51+G51+H51+M51 -> 1037.225
A52: =Collector!A53 -> Tanzania | B52: 100 | C52: 100 | D52: 20 | E52: =IF(Collector!E53="Yes",Collector!$D$64*$D$68,0) -> 0 | F52: =IF(Collector!E53="Yes",Collector!$D$66*$D$68,0) -> 0 | G52: =IF(Collector!F53="SADC VSAT",$D$61,0) -> 9.6 | H52: =IF(Collector!F53="NAFISAT",$D$62,0) -> 0 | I52: =IF(Collector!F53="AFISNET",$D$63,"n/a") -> n/a | J52: =Collector!M53 -> National unit rate x distance x sqrt(MTOW/50) | K52: =IF(Collector!P53="","—",Collector!P53) -> CAA permit fee and en-route unit rate published only in national AIP GEN 4 / AIC — obtain current circular. | L52: =$D$74 -> 50 | M52: =$D$75 -> 100 | N52: =$D$76 -> 40 | O52: =B52+E52+F52+G52+H52+L52 -> 159.6 | P52: =C52+E52+F52+G52+H52+M52 -> 209.6
A53: =Collector!A54 -> Togo | B53: 60 | C53: 60 | D53: 20 | E53: =IF(Collector!E54="Yes",Collector!$D$64*$D$68,0) -> 122.29812 | F53: =IF(Collector!E54="Yes",Collector!$D$66*$D$68,0) -> 244.60779 | G53: =IF(Collector!F54="SADC VSAT",$D$61,0) -> 0 | H53: =IF(Collector!F54="NAFISAT",$D$62,0) -> 0 | I53: =IF(Collector!F54="AFISNET",$D$63,"n/a") -> Not published separately | J53: =Collector!M54 -> ASECNA: unit charge x coefficient — see calculator rows 61-91 | K53: =IF(Collector!P54="","—",Collector!P54) -> CAA overflight/landing permit fee is an administrative charge — not published in AIP; obtain from CAA or handler. En-route billed by ASECNA. | L53: =$D$74 -> 50 | M53: =$D$75 -> 100 | N53: =$D$76 -> 40 | O53: =B53+E53+F53+G53+H53+L53 -> 476.90591 | P53: =C53+E53+F53+G53+H53+M53 -> 526.90591
A54: =Collector!A55 -> Tunisia | B54: 100 | C54: 100 | D54: 20 | E54: =IF(Collector!E55="Yes",Collector!$D$64*$D$68,0) -> 0 | F54: =IF(Collector!E55="Yes",Collector!$D$66*$D$68,0) -> 0 | G54: =IF(Collector!F55="SADC VSAT",$D$61,0) -> 0 | H54: =IF(Collector!F55="NAFISAT",$D$62,0) -> 10 | I54: =IF(Collector!F55="AFISNET",$D$63,"n/a") -> n/a | J54: =Collector!M55 -> National unit rate x distance x sqrt(MTOW/50) | K54: =IF(Collector!P55="","—",Collector!P55) -> CAA permit fee and en-route unit rate published only in national AIP GEN 4 / AIC — obtain current circular. | L54: =$D$74 -> 50 | M54: =$D$75 -> 100 | N54: =$D$76 -> 40 | O54: =B54+E54+F54+G54+H54+L54 -> 160 | P54: =C54+E54+F54+G54+H54+M54 -> 210
...
